<?xml version="1.0"?>
  <sdf version='1.6'>
    <world name='default'>
      <scene>
        <shadows>0</shadows>
        <ambient>0.4 0.4 0.4 1</ambient>
        <background>0.7 0.7 0.7 1</background>
      </scene>
      <light name='sun' type='directional'>
        <cast_shadows>1</cast_shadows>
        <pose frame=''>0 0 10 0 -0 0</pose>
        <diffuse>0.8 0.8 0.8 1</diffuse>
        <specular>0.2 0.2 0.2 1</specular>
        <attenuation>
          <range>1000</range>
          <constant>0.9</constant>
          <linear>0.01</linear>
          <quadratic>0.001</quadratic>
        </attenuation>
        <direction>-0.5 0.1 -0.9</direction>
      </light>
      <model name='ground_plane'>
        <static>1</static>
        <link name='link'>
          <collision name='collision'>
            <geometry>
              <plane>
                <normal>0 0 1</normal>
                <size>100 100</size>
              </plane>
            </geometry>
            <surface>
              <contact>
                <collide_bitmask>65535</collide_bitmask>
                <ode/>
              </contact>
              <friction>
                <ode>
                  <mu>100</mu>
                  <mu2>50</mu2>
                </ode>
                <torsional>
                  <ode/>
                </torsional>
              </friction>
              <bounce/>
            </surface>
            <max_contacts>10</max_contacts>
          </collision>
          <visual name='visual'>
            <cast_shadows>0</cast_shadows>
            <geometry>
              <plane>
                <normal>0 0 1</normal>
                <size>100 100</size>
              </plane>
            </geometry>
            <material>
              <script>
                <uri>file://media/materials/scripts/gazebo.material</uri>
                <name>Gazebo/Grey</name>
              </script>
            </material>
          </visual>
          <self_collide>0</self_collide>
          <enable_wind>0</enable_wind>
          <kinematic>0</kinematic>
        </link>
      </model>
      <model name='office'>
        <static>1</static>
        <link name='link'>
          <collision name='colision1'>
            <geometry>
              <mesh>
                <uri>model://office/meshes/SB_fixed.obj</uri>
              </mesh>
            </geometry>
            <max_contacts>10</max_contacts>
            <surface>
              <contact>
                <ode/>
              </contact>
              <bounce/>
              <friction>
                <torsional>
                  <ode/>
                </torsional>
                <ode/>
              </friction>
            </surface>
          </collision>
          <visual name='visual1'>
            <cast_shadows>1</cast_shadows>
            <geometry>
              <mesh>
                <uri>model://office/meshes/SB_fixed.obj</uri>
              </mesh>
            </geometry>
          </visual>
          <self_collide>0</self_collide>
          <enable_wind>0</enable_wind>
          <kinematic>0</kinematic>
        </link>
        <pose frame=''>0 0 0.08 0 -0 0</pose>
      </model>
      <model name='DropBox2'>
        <link name='link_0'>
          <pose frame=''>0 -0 0 0 0 -1.56873</pose>
          <inertial>
            <mass>1</mass>
            <inertia>
              <ixx>0.166667</ixx>
              <ixy>0</ixy>
              <ixz>0</ixz>
              <iyy>0.166667</iyy>
              <iyz>0</iyz>
              <izz>0.166667</izz>
            </inertia>
          </inertial>
          <visual name='visual'>
            <pose frame=''>0 0 0 0 -0 0</pose>
            <geometry>
              <mesh>
                <uri>model://dropbox/meshes/dropbox.dae</uri>
                <scale>1 1 1</scale>
              </mesh>
            </geometry>
            <material>
              <lighting>1</lighting>
              <script>
                <uri>file://media/materials/scripts/gazebo.material</uri>
                <name>Gazebo/Blue</name>
              </script>
              <ambient>0.3 0.3 0.3 1</ambient>
              <diffuse>0.7 0.7 0.7 1</diffuse>
              <specular>0.01 0.01 0.01 1</specular>
              <emissive>0 0 1 1</emissive>
            </material>
            <transparency>0</transparency>
            <cast_shadows>1</cast_shadows>
          </visual>
          <collision name='collision'>
            <laser_retro>0</laser_retro>
            <max_contacts>10</max_contacts>
            <pose frame=''>0 0 0 0 -0 0</pose>
            <geometry>
              <mesh>
                <uri>model://dropbox/meshes/dropbox.dae</uri>
                <scale>1 1 1</scale>
              </mesh>
            </geometry>
            <surface>
              <friction>
                <ode>
                  <mu>1</mu>
                  <mu2>1</mu2>
                  <fdir1>0 0 0</fdir1>
                  <slip1>0</slip1>
                  <slip2>0</slip2>
                </ode>
                <torsional>
                  <coefficient>1</coefficient>
                  <patch_radius>0</patch_radius>
                  <surface_radius>0</surface_radius>
                  <use_patch_radius>1</use_patch_radius>
                  <ode>
                    <slip>0</slip>
                  </ode>
                </torsional>
              </friction>
              <bounce>
                <restitution_coefficient>0</restitution_coefficient>
                <threshold>1e+06</threshold>
              </bounce>
              <contact>
                <collide_without_contact>0</collide_without_contact>
                <collide_without_contact_bitmask>1</collide_without_contact_bitmask>
                <collide_bitmask>1</collide_bitmask>
                <ode>
                  <soft_cfm>0</soft_cfm>
                  <soft_erp>0.2</soft_erp>
                  <kp>1e+13</kp>
                  <kd>1</kd>
                  <max_vel>0.01</max_vel>
                  <min_depth>0</min_depth>
                </ode>
                <bullet>
                  <split_impulse>1</split_impulse>
                  <split_impulse_penetration_threshold>-0.01</split_impulse_penetration_threshold>
                  <soft_cfm>0</soft_cfm>
                  <soft_erp>0.2</soft_erp>
                  <kp>1e+13</kp>
                  <kd>1</kd>
                </bullet>
              </contact>
            </surface>
          </collision>
          <self_collide>0</self_collide>
          <enable_wind>0</enable_wind>
          <kinematic>0</kinematic>
        </link>
        <static>1</static>
        <allow_auto_disable>1</allow_auto_disable>
        <pose frame=''>6.99 3.37 0.87 0 -0 0</pose>
      </model>
      <model name='DropBox1'>
        <link name='link_0'>
          <pose frame=''>0 -0 0 0 0 -1.56873</pose>
          <inertial>
            <mass>1</mass>
            <inertia>
              <ixx>0.166667</ixx>
              <ixy>0</ixy>
              <ixz>0</ixz>
              <iyy>0.166667</iyy>
              <iyz>0</iyz>
              <izz>0.166667</izz>
            </inertia>
          </inertial>
          <visual name='visual'>
            <pose frame=''>0 0 0 0 -0 0</pose>
            <geometry>
              <mesh>
                <uri>model://dropbox/meshes/dropbox.dae</uri>
                <scale>1 1 1</scale>
              </mesh>
            </geometry>
            <material>
              <lighting>1</lighting>
              <script>
                <uri>file://media/materials/scripts/gazebo.material</uri>
                <name>Gazebo/Blue</name>
              </script>
              <ambient>0.3 0.3 0.3 1</ambient>
              <diffuse>0.7 0.7 0.7 1</diffuse>
              <specular>0.01 0.01 0.01 1</specular>
              <emissive>0 0 1 1</emissive>
            </material>
            <transparency>0</transparency>
            <cast_shadows>1</cast_shadows>
          </visual>
          <collision name='collision'>
            <laser_retro>0</laser_retro>
            <max_contacts>10</max_contacts>
            <pose frame=''>0 0 0 0 -0 0</pose>
            <geometry>
              <mesh>
                <uri>model://dropbox/meshes/dropbox.dae</uri>
                <scale>1 1 1</scale>
              </mesh>
            </geometry>
            <surface>
              <friction>
                <ode>
                  <mu>1</mu>
                  <mu2>1</mu2>
                  <fdir1>0 0 0</fdir1>
                  <slip1>0</slip1>
                  <slip2>0</slip2>
                </ode>
                <torsional>
                  <coefficient>1</coefficient>
                  <patch_radius>0</patch_radius>
                  <surface_radius>0</surface_radius>
                  <use_patch_radius>1</use_patch_radius>
                  <ode>
                    <slip>0</slip>
                  </ode>
                </torsional>
              </friction>
              <bounce>
                <restitution_coefficient>0</restitution_coefficient>
                <threshold>1e+06</threshold>
              </bounce>
              <contact>
                <collide_without_contact>0</collide_without_contact>
                <collide_without_contact_bitmask>1</collide_without_contact_bitmask>
                <collide_bitmask>1</collide_bitmask>
                <ode>
                  <soft_cfm>0</soft_cfm>
                  <soft_erp>0.2</soft_erp>
                  <kp>1e+13</kp>
                  <kd>1</kd>
                  <max_vel>0.01</max_vel>
                  <min_depth>0</min_depth>
                </ode>
                <bullet>
                  <split_impulse>1</split_impulse>
                  <split_impulse_penetration_threshold>-0.01</split_impulse_penetration_threshold>
                  <soft_cfm>0</soft_cfm>
                  <soft_erp>0.2</soft_erp>
                  <kp>1e+13</kp>
                  <kd>1</kd>
                </bullet>
              </contact>
            </surface>
          </collision>
          <self_collide>0</self_collide>
          <enable_wind>0</enable_wind>
          <kinematic>0</kinematic>
        </link>
        <static>1</static>
        <allow_auto_disable>1</allow_auto_disable>
        <pose frame=''>5.61 -1.16 0.87 0 -0 0</pose>
      </model>
      <model name='DropBox3'>
        <link name='link_0'>
          <pose frame=''>0 -0 0 0 0 -1.56873</pose>
          <inertial>
            <mass>1</mass>
            <inertia>
              <ixx>0.166667</ixx>
              <ixy>0</ixy>
              <ixz>0</ixz>
              <iyy>0.166667</iyy>
              <iyz>0</iyz>
              <izz>0.166667</izz>
            </inertia>
          </inertial>
          <visual name='visual'>
            <pose frame=''>0 0 0 0 -0 0</pose>
            <geometry>
              <mesh>
                <uri>model://dropbox/meshes/dropbox.dae</uri>
                <scale>1 1 1</scale>
              </mesh>
            </geometry>
            <material>
              <lighting>1</lighting>
              <script>
                <uri>file://media/materials/scripts/gazebo.material</uri>
                <name>Gazebo/Blue</name>
              </script>
              <ambient>0.3 0.3 0.3 1</ambient>
              <diffuse>0.7 0.7 0.7 1</diffuse>
              <specular>0.01 0.01 0.01 1</specular>
              <emissive>0 0 1 1</emissive>
            </material>
            <transparency>0</transparency>
            <cast_shadows>1</cast_shadows>
          </visual>
          <collision name='collision'>
            <laser_retro>0</laser_retro>
            <max_contacts>10</max_contacts>
            <pose frame=''>0 0 0 0 -0 0</pose>
            <geometry>
              <mesh>
                <uri>model://dropbox/meshes/dropbox.dae</uri>
                <scale>1 1 1</scale>
              </mesh>
            </geometry>
            <surface>
              <friction>
                <ode>
                  <mu>1</mu>
                  <mu2>1</mu2>
                  <fdir1>0 0 0</fdir1>
                  <slip1>0</slip1>
                  <slip2>0</slip2>
                </ode>
                <torsional>
                  <coefficient>1</coefficient>
                  <patch_radius>0</patch_radius>
                  <surface_radius>0</surface_radius>
                  <use_patch_radius>1</use_patch_radius>
                  <ode>
                    <slip>0</slip>
                  </ode>
                </torsional>
              </friction>
              <bounce>
                <restitution_coefficient>0</restitution_coefficient>
                <threshold>1e+06</threshold>
              </bounce>
              <contact>
                <collide_without_contact>0</collide_without_contact>
                <collide_without_contact_bitmask>1</collide_without_contact_bitmask>
                <collide_bitmask>1</collide_bitmask>
                <ode>
                  <soft_cfm>0</soft_cfm>
                  <soft_erp>0.2</soft_erp>
                  <kp>1e+13</kp>
                  <kd>1</kd>
                  <max_vel>0.01</max_vel>
                  <min_depth>0</min_depth>
                </ode>
                <bullet>
                  <split_impulse>1</split_impulse>
                  <split_impulse_penetration_threshold>-0.01</split_impulse_penetration_threshold>
                  <soft_cfm>0</soft_cfm>
                  <soft_erp>0.2</soft_erp>
                  <kp>1e+13</kp>
                  <kd>1</kd>
                </bullet>
              </contact>
            </surface>
          </collision>
          <self_collide>0</self_collide>
          <enable_wind>0</enable_wind>
          <kinematic>0</kinematic>
        </link>
        <static>1</static>
        <allow_auto_disable>1</allow_auto_disable>
        <pose frame=''>11.64 9.51 0.87 0 -0 0</pose>
      </model>
      <model name='table'>
        <static>1</static>
        <link name='link'>
          <collision name='surface'>
            <pose frame=''>0 0 1 0 -0 0</pose>
            <geometry>
              <box>
                <size>1.5 0.8 0.03</size>
              </box>
            </geometry>
            <surface>
              <friction>
                <ode>
                  <mu>0.6</mu>
                  <mu2>0.6</mu2>
                </ode>
                <torsional>
                  <ode/>
                </torsional>
              </friction>
              <contact>
                <ode/>
              </contact>
              <bounce/>
            </surface>
            <max_contacts>10</max_contacts>
          </collision>
          <visual name='visual1'>
            <pose frame=''>0 0 1 0 -0 0</pose>
            <geometry>
              <box>
                <size>1.5 0.8 0.03</size>
              </box>
            </geometry>
            <material>
              <script>
                <uri>file://media/materials/scripts/gazebo.material</uri>
                <name>Gazebo/Wood</name>
              </script>
            </material>
          </visual>
          <collision name='front_left_leg'>
            <pose frame=''>0.68 0.38 0.5 0 -0 0</pose>
            <geometry>
              <cylinder>
                <radius>0.02</radius>
                <length>1</length>
              </cylinder>
            </geometry>
            <max_contacts>10</max_contacts>
            <surface>
              <contact>
                <ode/>
              </contact>
              <bounce/>
              <friction>
                <torsional>
                  <ode/>
                </torsional>
                <ode/>
              </friction>
            </surface>
          </collision>
          <visual name='front_left_leg'>
            <pose frame=''>0.68 0.38 0.5 0 -0 0</pose>
            <geometry>
              <cylinder>
                <radius>0.02</radius>
                <length>1</length>
              </cylinder>
            </geometry>
            <material>
              <script>
                <uri>file://media/materials/scripts/gazebo.material</uri>
                <name>Gazebo/Grey</name>
              </script>
            </material>
          </visual>
          <collision name='front_right_leg'>
            <pose frame=''>0.68 -0.38 0.5 0 -0 0</pose>
            <geometry>
              <cylinder>
                <radius>0.02</radius>
                <length>1</length>
              </cylinder>
            </geometry>
            <max_contacts>10</max_contacts>
            <surface>
              <contact>
                <ode/>
              </contact>
              <bounce/>
              <friction>
                <torsional>
                  <ode/>
                </torsional>
                <ode/>
              </friction>
            </surface>
          </collision>
          <visual name='front_right_leg'>
            <pose frame=''>0.68 -0.38 0.5 0 -0 0</pose>
            <geometry>
              <cylinder>
                <radius>0.02</radius>
                <length>1</length>
              </cylinder>
            </geometry>
            <material>
              <script>
                <uri>file://media/materials/scripts/gazebo.material</uri>
                <name>Gazebo/Grey</name>
              </script>
            </material>
          </visual>
          <collision name='back_right_leg'>
            <pose frame=''>-0.68 -0.38 0.5 0 -0 0</pose>
            <geometry>
              <cylinder>
                <radius>0.02</radius>
                <length>1</length>
              </cylinder>
            </geometry>
            <max_contacts>10</max_contacts>
            <surface>
              <contact>
                <ode/>
              </contact>
              <bounce/>
              <friction>
                <torsional>
                  <ode/>
                </torsional>
                <ode/>
              </friction>
            </surface>
          </collision>
          <visual name='back_right_leg'>
            <pose frame=''>-0.68 -0.38 0.5 0 -0 0</pose>
            <geometry>
              <cylinder>
                <radius>0.02</radius>
                <length>1</length>
              </cylinder>
            </geometry>
            <material>
              <script>
                <uri>file://media/materials/scripts/gazebo.material</uri>
                <name>Gazebo/Grey</name>
              </script>
            </material>
          </visual>
          <collision name='back_left_leg'>
            <pose frame=''>-0.68 0.38 0.5 0 -0 0</pose>
            <geometry>
              <cylinder>
                <radius>0.02</radius>
                <length>1</length>
              </cylinder>
            </geometry>
            <max_contacts>10</max_contacts>
            <surface>
              <contact>
                <ode/>
              </contact>
              <bounce/>
              <friction>
                <torsional>
                  <ode/>
                </torsional>
                <ode/>
              </friction>
            </surface>
          </collision>
          <visual name='back_left_leg'>
            <pose frame=''>-0.68 0.38 0.5 0 -0 0</pose>
            <geometry>
              <cylinder>
                <radius>0.02</radius>
                <length>1</length>
              </cylinder>
            </geometry>
            <material>
              <script>
                <uri>file://media/materials/scripts/gazebo.material</uri>
                <name>Gazebo/Grey</name>
              </script>
            </material>
          </visual>
          <self_collide>0</self_collide>
          <enable_wind>0</enable_wind>
          <kinematic>0</kinematic>
        </link>
        <pose frame=''>26.608 -3.569 0 0 -0 0.934</pose>
      </model>
      <gravity>0 0 -9.8</gravity>
      <magnetic_field>6e-06 2.3e-05 -4.2e-05</magnetic_field>
      <atmosphere type='adiabatic'/>
      <physics name='default_physics' default='0' type='ode'>
        <max_step_size>0.001</max_step_size>
        <real_time_factor>1</real_time_factor>
        <real_time_update_rate>1000</real_time_update_rate>
      </physics>
      <audio>
        <device>default</device>
      </audio>
      <wind/>
      <spherical_coordinates>
        <surface_model>EARTH_WGS84</surface_model>
        <latitude_deg>0</latitude_deg>
        <longitude_deg>0</longitude_deg>
        <elevation>0</elevation>
        <heading_deg>0</heading_deg>
      </spherical_coordinates>
      <model name='ebot'>
        <link name='ebot_base'>
          <pose frame=''>0 0 0 0 -0 0</pose>
          <inertial>
            <pose frame=''>0.000941 2e-06 0.169965 0 -0 0</pose>
            <mass>32.2426</mass>
            <inertia>
              <ixx>0.926622</ixx>
              <ixy>-5.5986e-05</ixy>
              <ixz>0.000783927</ixz>
              <iyy>1.52745</iyy>
              <iyz>8.09706e-06</iyz>
              <izz>1.03278</izz>
            </inertia>
          </inertial>
          <collision name='ebot_base_collision'>
            <pose frame=''>0 0 0.12 0 -0 0</pose>
            <geometry>
              <box>
                <size>0.585 0.3 0.25</size>
              </box>
            </geometry>
            <surface>
              <contact>
                <ode/>
              </contact>
              <friction>
                <ode/>
                <torsional>
                  <ode/>
                </torsional>
              </friction>
              <bounce/>
            </surface>
            <max_contacts>10</max_contacts>
          </collision>
          <collision name='ebot_base_fixed_joint_lump__FUS1_collision_1'>
            <pose frame=''>0.297826 -0.157279 0.097726 -1.5708 0 0.006797</pose>
            <geometry>
              <box>
                <size>0.019 0.057 0.028</size>
              </box>
            </geometry>
            <max_contacts>10</max_contacts>
            <surface>
              <contact>
                <ode/>
              </contact>
              <bounce/>
              <friction>
                <torsional>
                  <ode/>
                </torsional>
                <ode/>
              </friction>
            </surface>
          </collision>
          <collision name='ebot_base_fixed_joint_lump__FUS2_collision_2'>
            <pose frame=''>0.295787 0.142714 0.097726 -1.5708 0 0.006797</pose>
            <geometry>
              <box>
                <size>0.019 0.057 0.028</size>
              </box>
            </geometry>
            <max_contacts>10</max_contacts>
            <surface>
              <contact>
                <ode/>
              </contact>
              <bounce/>
              <friction>
                <torsional>
                  <ode/>
                </torsional>
                <ode/>
              </friction>
            </surface>
          </collision>
          <collision name='ebot_base_fixed_joint_lump__FUS3_collision_3'>
            <pose frame=''>0.272749 -0.074948 0.042475 0 0.785398 0.006797</pose>
            <geometry>
              <box>
                <size>0.019 0.057 0.028</size>
              </box>
            </geometry>
            <max_contacts>10</max_contacts>
            <surface>
              <contact>
                <ode/>
              </contact>
              <bounce/>
              <friction>
                <torsional>
                  <ode/>
                </torsional>
                <ode/>
              </friction>
            </surface>
          </collision>
          <collision name='ebot_base_fixed_joint_lump__FUS4_collision_4'>
            <pose frame=''>0.271702 0.079049 0.042475 0 0.785398 0.006797</pose>
            <geometry>
              <box>
                <size>0.019 0.057 0.028</size>
              </box>
            </geometry>
            <max_contacts>10</max_contacts>
            <surface>
              <contact>
                <ode/>
              </contact>
              <bounce/>
              <friction>
                <torsional>
                  <ode/>
                </torsional>
                <ode/>
              </friction>
            </surface>
          </collision>
          <collision name='ebot_base_fixed_joint_lump__LHUS10_collision_5'>
            <pose frame=''>0.14046 0.10004 0.196076 0.001869 0.123098 0.799849</pose>
            <geometry>
              <box>
                <size>0.019 0.057 0.028</size>
              </box>
            </geometry>
            <max_contacts>10</max_contacts>
            <surface>
              <contact>
                <ode/>
              </contact>
              <bounce/>
              <friction>
                <torsional>
                  <ode/>
                </torsional>
                <ode/>
              </friction>
            </surface>
          </collision>
          <collision name='ebot_base_fixed_joint_lump__LHUS9_collision_6'>
            <pose frame=''>-0.180601 0.145976 0.18945 0 -0 1.57759</pose>
            <geometry>
              <box>
                <size>0.019 0.057 0.028</size>
              </box>
            </geometry>
            <max_contacts>10</max_contacts>
            <surface>
              <contact>
                <ode/>
              </contact>
              <bounce/>
              <friction>
                <torsional>
                  <ode/>
                </torsional>
                <ode/>
              </friction>
            </surface>
          </collision>
          <collision name='ebot_base_fixed_joint_lump__RHUS7_collision_7'>
            <pose frame=''>-0.178602 -0.148017 0.18945 0 0 -1.564</pose>
            <geometry>
              <box>
                <size>0.019 0.057 0.028</size>
              </box>
            </geometry>
            <max_contacts>10</max_contacts>
            <surface>
              <contact>
                <ode/>
              </contact>
              <bounce/>
              <friction>
                <torsional>
                  <ode/>
                </torsional>
                <ode/>
              </friction>
            </surface>
          </collision>
          <collision name='ebot_base_fixed_joint_lump__RHUS9_collision_8'>
            <pose frame=''>0.141804 -0.097722 0.196076 -0.001869 0.123098 -0.786255</pose>
            <geometry>
              <box>
                <size>0.019 0.057 0.028</size>
              </box>
            </geometry>
            <max_contacts>10</max_contacts>
            <surface>
              <contact>
                <ode/>
              </contact>
              <bounce/>
              <friction>
                <torsional>
                  <ode/>
                </torsional>
                <ode/>
              </friction>
            </surface>
          </collision>
          <collision name='ebot_base_fixed_joint_lump__RUS5_collision_9'>
            <pose frame=''>-0.295329 0.157696 0.097703 -1.5708 0 -3.1348</pose>
            <geometry>
              <box>
                <size>0.019 0.057 0.028</size>
              </box>
            </geometry>
            <max_contacts>10</max_contacts>
            <surface>
              <contact>
                <ode/>
              </contact>
              <bounce/>
              <friction>
                <torsional>
                  <ode/>
                </torsional>
                <ode/>
              </friction>
            </surface>
          </collision>
          <collision name='ebot_base_fixed_joint_lump__RUS6_collision_10'>
            <pose frame=''>-0.29329 -0.142297 0.097703 -1.5708 0 -3.1348</pose>
            <geometry>
              <box>
                <size>0.019 0.057 0.028</size>
              </box>
            </geometry>
            <max_contacts>10</max_contacts>
            <surface>
              <contact>
                <ode/>
              </contact>
              <bounce/>
              <friction>
                <torsional>
                  <ode/>
                </torsional>
                <ode/>
              </friction>
            </surface>
          </collision>
          <collision name='ebot_base_fixed_joint_lump__base_link_collision_11'>
            <pose frame=''>0 0 0.521 0 -0 0</pose>
            <geometry>
              <cylinder>
                <length>0.024</length>
                <radius>0.0735</radius>
              </cylinder>
            </geometry>
            <max_contacts>10</max_contacts>
            <surface>
              <contact>
                <ode/>
              </contact>
              <bounce/>
              <friction>
                <torsional>
                  <ode/>
                </torsional>
                <ode/>
              </friction>
            </surface>
          </collision>
          <collision name='ebot_base_fixed_joint_lump__imu_link_collision_12'>
            <pose frame=''>0 0 0.2 0 -0 0</pose>
            <geometry>
              <box>
                <size>0.02 0.015 0.008</size>
              </box>
            </geometry>
            <surface>
              <contact>
                <ode/>
              </contact>
              <friction>
                <ode/>
                <torsional>
                  <ode/>
                </torsional>
              </friction>
              <bounce/>
            </surface>
            <max_contacts>10</max_contacts>
          </collision>
          <collision name='ebot_base_fixed_joint_lump__camera_link_collision_13'>
            <pose frame=''>0.297944 0.002084 0.023051 0 -0 0</pose>
            <geometry>
              <box>
                <size>0.001 0.001 0.001</size>
              </box>
            </geometry>
            <surface>
              <contact>
                <ode/>
              </contact>
              <friction>
                <ode/>
                <torsional>
                  <ode/>
                </torsional>
              </friction>
              <bounce/>
            </surface>
            <max_contacts>10</max_contacts>
          </collision>
          <collision name='ebot_base_fixed_joint_lump__laser_collision_14'>
            <pose frame=''>0.255541 0 0.18 0 -0 0.006797</pose>
            <geometry>
              <cylinder>
                <length>0.04</length>
                <radius>0.03</radius>
              </cylinder>
            </geometry>
            <surface>
              <contact>
                <ode/>
              </contact>
              <friction>
                <ode/>
                <torsional>
                  <ode/>
                </torsional>
              </friction>
              <bounce/>
            </surface>
            <max_contacts>10</max_contacts>
          </collision>
          <visual name='ebot_base_visual'>
            <pose frame=''>0 0 0 0 -0 0</pose>
            <geometry>
              <mesh>
                <scale>1 1 1</scale>
                <uri>/home/pranshu/ROS_WORKSPACES/Eyantra/src/sahayak_bot/ebot_description/meshes/chassis.STL</uri>
              </mesh>
            </geometry>
            <material>
              <script>
                <name>Gazebo/Grey</name>
                <uri>file://media/materials/scripts/gazebo.material</uri>
              </script>
            </material>
          </visual>
          <visual name='ebot_base_fixed_joint_lump__FUS1_visual_1'>
            <pose frame=''>0.297826 -0.157279 0.097726 -1.5708 0 0.006797</pose>
            <geometry>
              <mesh>
                <scale>1 1 1</scale>
                <uri>/home/pranshu/ROS_WORKSPACES/Eyantra/src/sahayak_bot/ebot_description/meshes/FUS1.STL</uri>
              </mesh>
            </geometry>
          </visual>
          <visual name='ebot_base_fixed_joint_lump__FUS2_visual_2'>
            <pose frame=''>0.295787 0.142714 0.097726 -1.5708 0 0.006797</pose>
            <geometry>
              <mesh>
                <scale>1 1 1</scale>
                <uri>/home/pranshu/ROS_WORKSPACES/Eyantra/src/sahayak_bot/ebot_description/meshes/FUS2.STL</uri>
              </mesh>
            </geometry>
          </visual>
          <visual name='ebot_base_fixed_joint_lump__FUS3_visual_3'>
            <pose frame=''>0.272749 -0.074948 0.042475 0 0.785398 0.006797</pose>
            <geometry>
              <mesh>
                <scale>1 1 1</scale>
                <uri>/home/pranshu/ROS_WORKSPACES/Eyantra/src/sahayak_bot/ebot_description/meshes/FUS3.STL</uri>
              </mesh>
            </geometry>
          </visual>
          <visual name='ebot_base_fixed_joint_lump__FUS4_visual_4'>
            <pose frame=''>0.271702 0.079049 0.042475 0 0.785398 0.006797</pose>
            <geometry>
              <mesh>
                <scale>1 1 1</scale>
                <uri>/home/pranshu/ROS_WORKSPACES/Eyantra/src/sahayak_bot/ebot_description/meshes/FUS4.STL</uri>
              </mesh>
            </geometry>
          </visual>
          <visual name='ebot_base_fixed_joint_lump__LHUS10_visual_5'>
            <pose frame=''>0.14046 0.10004 0.196076 0.001869 0.123098 0.799849</pose>
            <geometry>
              <mesh>
                <scale>1 1 1</scale>
                <uri>/home/pranshu/ROS_WORKSPACES/Eyantra/src/sahayak_bot/ebot_description/meshes/LHUS10.STL</uri>
              </mesh>
            </geometry>
          </visual>
          <visual name='ebot_base_fixed_joint_lump__LHUS9_visual_6'>
            <pose frame=''>-0.180601 0.145976 0.18945 0 -0 1.57759</pose>
            <geometry>
              <mesh>
                <scale>1 1 1</scale>
                <uri>/home/pranshu/ROS_WORKSPACES/Eyantra/src/sahayak_bot/ebot_description/meshes/LHUS9.STL</uri>
              </mesh>
            </geometry>
          </visual>
          <visual name='ebot_base_fixed_joint_lump__RHUS7_visual_7'>
            <pose frame=''>-0.178602 -0.148017 0.18945 0 0 -1.564</pose>
            <geometry>
              <mesh>
                <scale>1 1 1</scale>
                <uri>/home/pranshu/ROS_WORKSPACES/Eyantra/src/sahayak_bot/ebot_description/meshes/RHUS7.STL</uri>
              </mesh>
            </geometry>
          </visual>
          <visual name='ebot_base_fixed_joint_lump__RHUS9_visual_8'>
            <pose frame=''>0.141804 -0.097722 0.196076 -0.001869 0.123098 -0.786255</pose>
            <geometry>
              <mesh>
                <scale>1 1 1</scale>
                <uri>/home/pranshu/ROS_WORKSPACES/Eyantra/src/sahayak_bot/ebot_description/meshes/RHUS9.STL</uri>
              </mesh>
            </geometry>
          </visual>
          <visual name='ebot_base_fixed_joint_lump__RUS5_visual_9'>
            <pose frame=''>-0.295329 0.157696 0.097703 -1.5708 0 -3.1348</pose>
            <geometry>
              <mesh>
                <scale>1 1 1</scale>
                <uri>/home/pranshu/ROS_WORKSPACES/Eyantra/src/sahayak_bot/ebot_description/meshes/RUS5.STL</uri>
              </mesh>
            </geometry>
          </visual>
          <visual name='ebot_base_fixed_joint_lump__RUS6_visual_10'>
            <pose frame=''>-0.29329 -0.142297 0.097703 -1.5708 0 -3.1348</pose>
            <geometry>
              <mesh>
                <scale>1 1 1</scale>
                <uri>/home/pranshu/ROS_WORKSPACES/Eyantra/src/sahayak_bot/ebot_description/meshes/RUS6.STL</uri>
              </mesh>
            </geometry>
          </visual>
          <visual name='ebot_base_fixed_joint_lump__base_link_visual_11'>
            <pose frame=''>0 0 0.521 0 -0 0</pose>
            <geometry>
              <mesh>
                <scale>1 1 1</scale>
                <uri>/home/pranshu/ROS_WORKSPACES/Eyantra/src/sahayak_bot/ur_description/meshes/ur5/visual/base.dae</uri>
              </mesh>
            </geometry>
          </visual>
          <visual name='ebot_base_fixed_joint_lump__imu_link_visual_12'>
            <pose frame=''>0 0 0.2 0 -0 0</pose>
            <geometry>
              <box>
                <size>0.02 0.015 0.008</size>
              </box>
            </geometry>
            <material>
              <script>
                <uri>__default__</uri>
                <name>__default__</name>
              </script>
            </material>
          </visual>
          <visual name='ebot_base_fixed_joint_lump__camera_link_visual_13'>
            <pose frame=''>0.277944 0.002084 0.023051 1.5707 0 1.5707</pose>
            <geometry>
              <mesh>
                <scale>1 1 1</scale>
                <uri>/home/pranshu/ROS_WORKSPACES/Eyantra/src/sahayak_bot/ebot_description/meshes/NAVRS.STL</uri>
              </mesh>
            </geometry>
            <material>
              <script>
                <name>Gazebo/Black</name>
                <uri>file://media/materials/scripts/gazebo.material</uri>
              </script>
            </material>
          </visual>
          <visual name='ebot_base_fixed_joint_lump__laser_visual_14'>
            <pose frame=''>0.255541 0 0.18 0 -0 0.006797</pose>
            <geometry>
              <cylinder>
                <length>0.04</length>
                <radius>0.03</radius>
              </cylinder>
            </geometry>
            <material>
              <script>
                <name>Gazebo/Black</name>
                <uri>file://media/materials/scripts/gazebo.material</uri>
              </script>
            </material>
          </visual>
          <velocity_decay/>
          <velocity_decay/>
          <sensor name='imu_sensor' type='imu'>
            <always_on>1</always_on>
            <update_rate>100</update_rate>
            <visualize>1</visualize>
            <topic>__default_topic__</topic>
            <plugin name='imu_plugin' filename='libgazebo_ros_imu_sensor.so'>
              <topicName>imu</topicName>
              <bodyName>imu_link</bodyName>
              <updateRateHZ>10.0</updateRateHZ>
              <gaussianNoise>0.0</gaussianNoise>
              <xyzOffset>0 0 0</xyzOffset>
              <rpyOffset>0 0 0</rpyOffset>
              <frameName>imu_link</frameName>
              <initialOrientationAsReference>0</initialOrientationAsReference>
              <robotNamespace>/</robotNamespace>
            </plugin>
            <pose frame=''>0 0 0.2 0 -0 0</pose>
            <imu/>
          </sensor>
          <velocity_decay/>
          <velocity_decay/>
          <sensor name='intelrealsenseD435i' type='depth'>
            <always_on>1</always_on>
            <visualize>1</visualize>
            <camera name='__default__'>
              <horizontal_fov>1.047</horizontal_fov>
              <image>
                <width>640</width>
                <height>480</height>
                <format>R8G8B8</format>
              </image>
              <depth_camera>
                <output>depths</output>
              </depth_camera>
              <clip>
                <near>0.1</near>
                <far>100</far>
              </clip>
            </camera>
            <plugin name='intelrealsense' filename='libgazebo_ros_openni_kinect.so'>
              <alwaysOn>1</alwaysOn>
              <updateRate>10.0</updateRate>
              <cameraName>camera</cameraName>
              <frameName>camera_depth_frame</frameName>
              <imageTopicName>/camera/color/image_raw</imageTopicName>
              <depthImageTopicName>/camera/depth/image_rect_raw</depthImageTopicName>
              <pointCloudTopicName>depth/points</pointCloudTopicName>
              <cameraInfoTopicName>/camera/color/camera_info</cameraInfoTopicName>
              <depthImageCameraInfoTopicName>/camera/depth/camera_info</depthImageCameraInfoTopicName>
              <pointCloudCutoff>0.2</pointCloudCutoff>
              <pointCloudCutoffMax>10.0</pointCloudCutoffMax>
              <hackBaseline>0.07</hackBaseline>
              <distortionK1>0.0</distortionK1>
              <distortionK2>0.0</distortionK2>
              <distortionK3>0.0</distortionK3>
              <distortionT1>0.0</distortionT1>
              <distortionT2>0.0</distortionT2>
              <CxPrime>0.0</CxPrime>
              <Cx>0.0</Cx>
              <Cy>0.0</Cy>
              <focalLength>0.0</focalLength>
              <robotNamespace>/</robotNamespace>
            </plugin>
            <pose frame=''>0.277944 0.002084 0.023051 0 -0 0</pose>
          </sensor>
          <gravity>1</gravity>
          <velocity_decay/>
          <gravity>1</gravity>
          <velocity_decay/>
          <sensor name='head_rplidar_sensor' type='ray'>
            <visualize>0</visualize>
            <update_rate>40</update_rate>
            <ray>
              <scan>
                <horizontal>
                  <samples>720</samples>
                  <resolution>1</resolution>
                  <min_angle>-2.35619</min_angle>
                  <max_angle>2.35619</max_angle>
                </horizontal>
                <vertical>
                  <samples>1</samples>
                  <min_angle>0</min_angle>
                  <max_angle>0</max_angle>
                </vertical>
              </scan>
              <range>
                <min>0.5</min>
                <max>20</max>
                <resolution>0.01</resolution>
              </range>
              <noise>
                <type>gaussian</type>
                <mean>0</mean>
                <stddev>0.01</stddev>
              </noise>
            </ray>
            <plugin name='gazebo_ros_head_rplidar_controller' filename='libgazebo_ros_laser.so'>
              <topicName>/ebot/laser/scan</topicName>
              <frameName>laser</frameName>
              <robotNamespace>/</robotNamespace>
            </plugin>
            <pose frame=''>0.255541 0 0.18 0 -0 0.006797</pose>
          </sensor>
          <self_collide>0</self_collide>
          <enable_wind>0</enable_wind>
          <kinematic>0</kinematic>
        </link>
        <link name='FWL'>
          <pose frame=''>0.199948 0.192163 0.045 0 -0 0.006797</pose>
          <inertial>
            <pose frame=''>6.7e-05 0.025016 -1e-06 0 -0 0</pose>
            <mass>0.7</mass>
            <inertia>
              <ixx>0.003</ixx>
              <ixy>0</ixy>
              <ixz>0</ixz>
              <iyy>0.003</iyy>
              <iyz>0</iyz>
              <izz>0.0035</izz>
            </inertia>
          </inertial>
          <collision name='FWL_collision'>
            <pose frame=''>0 0.025 0 -3.14159 1.57079 1.57079</pose>
            <geometry>
              <cylinder>
                <length>0.05</length>
                <radius>0.1</radius>
              </cylinder>
            </geometry>
            <surface>
              <contact>
                <ode/>
              </contact>
              <friction>
                <ode/>
                <torsional>
                  <ode/>
                </torsional>
              </friction>
              <bounce/>
            </surface>
            <max_contacts>10</max_contacts>
          </collision>
          <visual name='FWL_visual'>
            <pose frame=''>0 0 0 0 -0 0</pose>
            <geometry>
              <mesh>
                <scale>1 1 1</scale>
                <uri>/home/pranshu/ROS_WORKSPACES/Eyantra/src/sahayak_bot/ebot_description/meshes/FWL.STL</uri>
              </mesh>
            </geometry>
            <material>
              <script>
                <name>Gazebo/Black</name>
                <uri>file://media/materials/scripts/gazebo.material</uri>
              </script>
            </material>
          </visual>
          <gravity>1</gravity>
          <velocity_decay/>
          <self_collide>0</self_collide>
          <enable_wind>0</enable_wind>
          <kinematic>0</kinematic>
        </link>
        <joint name='FWLJ' type='revolute'>
          <child>FWL</child>
          <parent>ebot_base</parent>
          <axis>
            <xyz>-0.006797 0.999977 0</xyz>
            <limit>
              <lower>-1e+16</lower>
              <upper>1e+16</upper>
            </limit>
            <dynamics>
              <spring_reference>0</spring_reference>
              <spring_stiffness>0</spring_stiffness>
            </dynamics>
            <use_parent_model_frame>1</use_parent_model_frame>
          </axis>
        </joint>
        <link name='FWR'>
          <pose frame=''>0.20254 -0.189028 0.045 -3.14159 0.911096 0.006797</pose>
          <inertial>
            <pose frame=''>6.7e-05 0.025016 -1e-06 0 -0 0</pose>
            <mass>0.7</mass>
            <inertia>
              <ixx>0.003</ixx>
              <ixy>0</ixy>
              <ixz>0</ixz>
              <iyy>0.003</iyy>
              <iyz>0</iyz>
              <izz>0.0035</izz>
            </inertia>
          </inertial>
          <collision name='FWR_collision'>
            <pose frame=''>0 0.025 0 -3.14159 1.57079 1.57079</pose>
            <geometry>
              <cylinder>
                <length>0.05</length>
                <radius>0.1</radius>
              </cylinder>
            </geometry>
            <surface>
              <contact>
                <ode/>
              </contact>
              <friction>
                <ode/>
                <torsional>
                  <ode/>
                </torsional>
              </friction>
              <bounce/>
            </surface>
            <max_contacts>10</max_contacts>
          </collision>
          <visual name='FWR_visual'>
            <pose frame=''>0 0 0 0 -0 0</pose>
            <geometry>
              <mesh>
                <scale>1 1 1</scale>
                <uri>/home/pranshu/ROS_WORKSPACES/Eyantra/src/sahayak_bot/ebot_description/meshes/FWR.STL</uri>
              </mesh>
            </geometry>
            <material>
              <script>
                <name>Gazebo/Black</name>
                <uri>file://media/materials/scripts/gazebo.material</uri>
              </script>
            </material>
          </visual>
          <gravity>1</gravity>
          <velocity_decay/>
          <self_collide>0</self_collide>
          <enable_wind>0</enable_wind>
          <kinematic>0</kinematic>
        </link>
        <joint name='FWRJ' type='revolute'>
          <child>FWR</child>
          <parent>ebot_base</parent>
          <axis>
            <xyz>-0.006797 0.999977 0</xyz>
            <limit>
              <lower>-1e+16</lower>
              <upper>1e+16</upper>
            </limit>
            <dynamics>
              <spring_reference>0</spring_reference>
              <spring_stiffness>0</spring_stiffness>
            </dynamics>
            <use_parent_model_frame>1</use_parent_model_frame>
          </axis>
        </joint>
        <link name='RWL'>
          <pose frame=''>-0.200042 0.189445 0.045 0 -0 0.006797</pose>
          <inertial>
            <pose frame=''>6.7e-05 0.025016 -1e-06 0 -0 0</pose>
            <mass>0.7</mass>
            <inertia>
              <ixx>0.003</ixx>
              <ixy>0</ixy>
              <ixz>0</ixz>
              <iyy>0.003</iyy>
              <iyz>0</iyz>
              <izz>0.0035</izz>
            </inertia>
          </inertial>
          <collision name='RWL_collision'>
            <pose frame=''>0 0.025 0 -3.14159 1.57079 1.57079</pose>
            <geometry>
              <cylinder>
                <length>0.05</length>
                <radius>0.1</radius>
              </cylinder>
            </geometry>
            <surface>
              <contact>
                <ode/>
              </contact>
              <friction>
                <ode/>
                <torsional>
                  <ode/>
                </torsional>
              </friction>
              <bounce/>
            </surface>
            <max_contacts>10</max_contacts>
          </collision>
          <visual name='RWL_visual'>
            <pose frame=''>0 0 0 0 -0 0</pose>
            <geometry>
              <mesh>
                <scale>1 1 1</scale>
                <uri>/home/pranshu/ROS_WORKSPACES/Eyantra/src/sahayak_bot/ebot_description/meshes/RWL.STL</uri>
              </mesh>
            </geometry>
            <material>
              <script>
                <name>Gazebo/Black</name>
                <uri>file://media/materials/scripts/gazebo.material</uri>
              </script>
            </material>
          </visual>
          <gravity>1</gravity>
          <velocity_decay/>
          <self_collide>0</self_collide>
          <enable_wind>0</enable_wind>
          <kinematic>0</kinematic>
        </link>
        <joint name='RWLJ' type='revolute'>
          <child>RWL</child>
          <parent>ebot_base</parent>
          <axis>
            <xyz>-0.006797 0.999977 0</xyz>
            <limit>
              <lower>-1e+16</lower>
              <upper>1e+16</upper>
            </limit>
            <dynamics>
              <spring_reference>0</spring_reference>
              <spring_stiffness>0</spring_stiffness>
            </dynamics>
            <use_parent_model_frame>1</use_parent_model_frame>
          </axis>
        </joint>
        <link name='RWR'>
          <pose frame=''>-0.197451 -0.191747 0.045 -3.14159 0.544912 0.006797</pose>
          <inertial>
            <pose frame=''>6.7e-05 0.025016 -1e-06 0 -0 0</pose>
            <mass>0.7</mass>
            <inertia>
              <ixx>0.003</ixx>
              <ixy>0</ixy>
              <ixz>0</ixz>
              <iyy>0.003</iyy>
              <iyz>0</iyz>
              <izz>0.0035</izz>
            </inertia>
          </inertial>
          <collision name='RWR_collision'>
            <pose frame=''>0 0.025 0 -3.14159 1.57079 1.57079</pose>
            <geometry>
              <cylinder>
                <length>0.05</length>
                <radius>0.1</radius>
              </cylinder>
            </geometry>
            <surface>
              <contact>
                <ode/>
              </contact>
              <friction>
                <ode/>
                <torsional>
                  <ode/>
                </torsional>
              </friction>
              <bounce/>
            </surface>
            <max_contacts>10</max_contacts>
          </collision>
          <visual name='RWR_visual'>
            <pose frame=''>0 0 0 0 -0 0</pose>
            <geometry>
              <mesh>
                <scale>1 1 1</scale>
                <uri>/home/pranshu/ROS_WORKSPACES/Eyantra/src/sahayak_bot/ebot_description/meshes/RWR.STL</uri>
              </mesh>
            </geometry>
            <material>
              <script>
                <name>Gazebo/Black</name>
                <uri>file://media/materials/scripts/gazebo.material</uri>
              </script>
            </material>
          </visual>
          <gravity>1</gravity>
          <velocity_decay/>
          <self_collide>0</self_collide>
          <enable_wind>0</enable_wind>
          <kinematic>0</kinematic>
        </link>
        <joint name='RWRJ' type='revolute'>
          <child>RWR</child>
          <parent>ebot_base</parent>
          <axis>
            <xyz>-0.006797 0.999977 0</xyz>
            <limit>
              <lower>-1e+16</lower>
              <upper>1e+16</upper>
            </limit>
            <dynamics>
              <spring_reference>0</spring_reference>
              <spring_stiffness>0</spring_stiffness>
            </dynamics>
            <use_parent_model_frame>1</use_parent_model_frame>
          </axis>
        </joint>
        <link name='shoulder_link'>
          <pose frame=''>0 0 0.610159 0 -0 0</pose>
          <inertial>
            <pose frame=''>0 0 0 0 -0 0</pose>
            <mass>3.7</mass>
            <inertia>
              <ixx>0.0102675</ixx>
              <ixy>0</ixy>
              <ixz>0</ixz>
              <iyy>0.0102675</iyy>
              <iyz>0</iyz>
              <izz>0.00666</izz>
            </inertia>
          </inertial>
          <collision name='shoulder_link_collision'>
            <pose frame=''>0 0 0 0 -0 0</pose>
            <geometry>
              <cylinder>
                <length>0.134</length>
                <radius>0.0595</radius>
              </cylinder>
            </geometry>
            <surface>
              <contact>
                <ode/>
              </contact>
              <friction>
                <ode/>
                <torsional>
                  <ode/>
                </torsional>
              </friction>
              <bounce/>
            </surface>
            <max_contacts>10</max_contacts>
          </collision>
          <visual name='shoulder_link_visual'>
            <pose frame=''>0 0 0 0 -0 0</pose>
            <geometry>
              <mesh>
                <scale>1 1 1</scale>
                <uri>/home/pranshu/ROS_WORKSPACES/Eyantra/src/sahayak_bot/ur_description/meshes/ur5/visual/shoulder.dae</uri>
              </mesh>
            </geometry>
            <material>
              <script>
                <uri>__default__</uri>
                <name>__default__</name>
              </script>
            </material>
          </visual>
          <gravity>1</gravity>
          <velocity_decay/>
          <self_collide>1</self_collide>
          <enable_wind>0</enable_wind>
          <kinematic>0</kinematic>
        </link>
        <joint name='shoulder_pan_joint' type='revolute'>
          <child>shoulder_link</child>
          <parent>ebot_base</parent>
          <axis>
            <xyz>0 0 1</xyz>
            <limit>
              <lower>-6.28319</lower>
              <upper>6.28319</upper>
              <effort>150</effort>
              <velocity>3.15</velocity>
            </limit>
            <dynamics>
              <damping>0</damping>
              <friction>0</friction>
              <spring_reference>0</spring_reference>
              <spring_stiffness>0</spring_stiffness>
            </dynamics>
            <use_parent_model_frame>1</use_parent_model_frame>
          </axis>
        </joint>
        <link name='upper_arm_link'>
          <pose frame=''>0 0.13585 0.610159 0 -0 0</pose>
          <inertial>
            <pose frame=''>0 0 0.28 0 -0 0</pose>
            <mass>8.393</mass>
            <inertia>
              <ixx>0.226891</ixx>
              <ixy>0</ixy>
              <ixz>0</ixz>
              <iyy>0.226891</iyy>
              <iyz>0</iyz>
              <izz>0.0151074</izz>
            </inertia>
          </inertial>
          <collision name='upper_arm_link_collision'>
            <pose frame=''>0 0 0.22 0 -0 0</pose>
            <geometry>
              <cylinder>
                <length>0.545</length>
                <radius>0.045</radius>
              </cylinder>
            </geometry>
            <surface>
              <contact>
                <ode/>
              </contact>
              <friction>
                <ode/>
                <torsional>
                  <ode/>
                </torsional>
              </friction>
              <bounce/>
            </surface>
            <max_contacts>10</max_contacts>
          </collision>
          <visual name='upper_arm_link_visual'>
            <pose frame=''>0 0 0 0 -0 0</pose>
            <geometry>
              <mesh>
                <scale>1 1 1</scale>
                <uri>/home/pranshu/ROS_WORKSPACES/Eyantra/src/sahayak_bot/ur_description/meshes/ur5/visual/upperarm.dae</uri>
              </mesh>
            </geometry>
            <material>
              <script>
                <uri>__default__</uri>
                <name>__default__</name>
              </script>
            </material>
          </visual>
          <gravity>1</gravity>
          <velocity_decay/>
          <self_collide>1</self_collide>
          <enable_wind>0</enable_wind>
          <kinematic>0</kinematic>
        </link>
        <joint name='shoulder_lift_joint' type='revolute'>
          <child>upper_arm_link</child>
          <parent>shoulder_link</parent>
          <axis>
            <xyz>0 1 0</xyz>
            <limit>
              <lower>-6.28319</lower>
              <upper>6.28319</upper>
              <effort>150</effort>
              <velocity>3.15</velocity>
            </limit>
            <dynamics>
              <damping>0</damping>
              <friction>0</friction>
              <spring_reference>0</spring_reference>
              <spring_stiffness>0</spring_stiffness>
            </dynamics>
            <use_parent_model_frame>1</use_parent_model_frame>
          </axis>
        </joint>
        <link name='forearm_link'>
          <pose frame=''>0 0.01615 1.03516 3.14159 1.0472 3.14159</pose>
          <inertial>
            <pose frame=''>0 0 0.196125 0 -0 0</pose>
            <mass>2.275</mass>
            <inertia>
              <ixx>0.0312168</ixx>
              <ixy>0</ixy>
              <ixz>0</ixz>
              <iyy>0.0312168</iyy>
              <iyz>0</iyz>
              <izz>0.004095</izz>
            </inertia>
          </inertial>
          <collision name='forearm_link_collision'>
            <pose frame=''>0 0 0.18 0 -0 0</pose>
            <geometry>
              <cylinder>
                <length>0.489</length>
                <radius>0.038</radius>
              </cylinder>
            </geometry>
            <surface>
              <contact>
                <ode/>
              </contact>
              <friction>
                <ode/>
                <torsional>
                  <ode/>
                </torsional>
              </friction>
              <bounce/>
            </surface>
            <max_contacts>10</max_contacts>
          </collision>
          <visual name='forearm_link_visual'>
            <pose frame=''>0 0 0 0 -0 0</pose>
            <geometry>
              <mesh>
                <scale>1 1 1</scale>
                <uri>/home/pranshu/ROS_WORKSPACES/Eyantra/src/sahayak_bot/ur_description/meshes/ur5/visual/forearm.dae</uri>
              </mesh>
            </geometry>
            <material>
              <script>
                <uri>__default__</uri>
                <name>__default__</name>
              </script>
            </material>
          </visual>
          <gravity>1</gravity>
          <velocity_decay/>
          <self_collide>1</self_collide>
          <enable_wind>0</enable_wind>
          <kinematic>0</kinematic>
        </link>
        <joint name='elbow_joint' type='revolute'>
          <child>forearm_link</child>
          <parent>upper_arm_link</parent>
          <axis>
            <xyz>0 1 0</xyz>
            <limit>
              <lower>-3.14159</lower>
              <upper>3.14159</upper>
              <effort>150</effort>
              <velocity>3.15</velocity>
            </limit>
            <dynamics>
              <damping>0</damping>
              <friction>0</friction>
              <spring_reference>0</spring_reference>
              <spring_stiffness>0</spring_stiffness>
            </dynamics>
            <use_parent_model_frame>1</use_parent_model_frame>
          </axis>
        </joint>
        <link name='wrist_1_link'>
          <pose frame=''>0.339698 0.01615 0.839034 3.14159 -0.523599 3.14159</pose>
          <inertial>
            <pose frame=''>0 0.093 0 0 -0 0</pose>
            <mass>1.219</mass>
            <inertia>
              <ixx>0.0025599</ixx>
              <ixy>0</ixy>
              <ixz>0</ixz>
              <iyy>0.0025599</iyy>
              <iyz>0</iyz>
              <izz>0.0021942</izz>
            </inertia>
          </inertial>
          <collision name='wrist_1_link_collision'>
            <pose frame=''>0 0.093 0.008 0 -0 0</pose>
            <geometry>
              <cylinder>
                <length>0.1</length>
                <radius>0.032</radius>
              </cylinder>
            </geometry>
            <surface>
              <contact>
                <ode/>
              </contact>
              <friction>
                <ode/>
                <torsional>
                  <ode/>
                </torsional>
              </friction>
              <bounce/>
            </surface>
            <max_contacts>10</max_contacts>
          </collision>
          <visual name='wrist_1_link_visual'>
            <pose frame=''>0 0 0 0 -0 0</pose>
            <geometry>
              <mesh>
                <scale>1 1 1</scale>
                <uri>/home/pranshu/ROS_WORKSPACES/Eyantra/src/sahayak_bot/ur_description/meshes/ur5/visual/wrist1.dae</uri>
              </mesh>
            </geometry>
            <material>
              <script>
                <uri>__default__</uri>
                <name>__default__</name>
              </script>
            </material>
          </visual>
          <gravity>1</gravity>
          <velocity_decay/>
          <self_collide>1</self_collide>
          <enable_wind>0</enable_wind>
          <kinematic>0</kinematic>
        </link>
        <joint name='wrist_1_joint' type='revolute'>
          <child>wrist_1_link</child>
          <parent>forearm_link</parent>
          <axis>
            <xyz>0 1 0</xyz>
            <limit>
              <lower>-6.28319</lower>
              <upper>6.28319</upper>
              <effort>28</effort>
              <velocity>3.2</velocity>
            </limit>
            <dynamics>
              <damping>0</damping>
              <friction>0</friction>
              <spring_reference>0</spring_reference>
              <spring_stiffness>0</spring_stiffness>
            </dynamics>
            <use_parent_model_frame>1</use_parent_model_frame>
          </axis>
        </joint>
        <link name='wrist_2_link'>
          <pose frame=''>0.339698 0.10915 0.839034 3.14159 -0.523599 3.14159</pose>
          <inertial>
            <pose frame=''>0 0 0.09465 0 -0 0</pose>
            <mass>1.219</mass>
            <inertia>
              <ixx>0.0025599</ixx>
              <ixy>0</ixy>
              <ixz>0</ixz>
              <iyy>0.0025599</iyy>
              <iyz>0</iyz>
              <izz>0.0021942</izz>
            </inertia>
          </inertial>
          <collision name='wrist_2_link_collision'>
            <pose frame=''>0 0 0.09465 1.57 -0 0</pose>
            <geometry>
              <cylinder>
                <length>0.105</length>
                <radius>0.032</radius>
              </cylinder>
            </geometry>
            <surface>
              <contact>
                <ode/>
              </contact>
              <friction>
                <ode/>
                <torsional>
                  <ode/>
                </torsional>
              </friction>
              <bounce/>
            </surface>
            <max_contacts>10</max_contacts>
          </collision>
          <visual name='wrist_2_link_visual'>
            <pose frame=''>0 0 0 0 -0 0</pose>
            <geometry>
              <mesh>
                <scale>1 1 1</scale>
                <uri>/home/pranshu/ROS_WORKSPACES/Eyantra/src/sahayak_bot/ur_description/meshes/ur5/visual/wrist2.dae</uri>
              </mesh>
            </geometry>
            <material>
              <script>
                <uri>__default__</uri>
                <name>__default__</name>
              </script>
            </material>
          </visual>
          <gravity>1</gravity>
          <velocity_decay/>
          <self_collide>1</self_collide>
          <enable_wind>0</enable_wind>
          <kinematic>0</kinematic>
        </link>
        <joint name='wrist_2_joint' type='revolute'>
          <child>wrist_2_link</child>
          <parent>wrist_1_link</parent>
          <axis>
            <xyz>-0.5 0 -0.866025</xyz>
            <limit>
              <lower>-6.28319</lower>
              <upper>6.28319</upper>
              <effort>28</effort>
              <velocity>3.2</velocity>
            </limit>
            <dynamics>
              <damping>0</damping>
              <friction>0</friction>
              <spring_reference>0</spring_reference>
              <spring_stiffness>0</spring_stiffness>
            </dynamics>
            <use_parent_model_frame>1</use_parent_model_frame>
          </axis>
        </joint>
        <link name='wrist_3_link'>
          <pose frame=''>0.292373 0.10915 0.757065 3.14159 -0.523599 3.14159</pose>
          <inertial>
            <pose frame=''>0 0.092039 -1e-06 1.5708 -0 0</pose>
            <mass>0.824861</mass>
            <inertia>
              <ixx>0.001372</ixx>
              <ixy>-1.75029e-26</ixy>
              <ixz>3.57451e-15</ixz>
              <iyy>0.00143293</iyy>
              <iyz>-6.36917e-09</iyz>
              <izz>0.000512181</izz>
            </inertia>
          </inertial>
          <collision name='wrist_3_link_collision'>
            <pose frame=''>0 0.067 0 1.57 -0 0</pose>
            <geometry>
              <cylinder>
                <length>0.0245</length>
                <radius>0.032</radius>
              </cylinder>
            </geometry>
            <surface>
              <contact>
                <ode/>
              </contact>
              <friction>
                <ode/>
                <torsional>
                  <ode/>
                </torsional>
              </friction>
              <bounce/>
            </surface>
            <max_contacts>10</max_contacts>
          </collision>
          <collision name='wrist_3_link_fixed_joint_lump__ee_link_collision_1'>
            <pose frame=''>-0 0.0723 0 0 -0 1.5708</pose>
            <geometry>
              <box>
                <size>0.01 0.01 0.01</size>
              </box>
            </geometry>
            <surface>
              <contact>
                <ode/>
              </contact>
              <friction>
                <ode/>
                <torsional>
                  <ode/>
                </torsional>
              </friction>
              <bounce/>
            </surface>
            <max_contacts>10</max_contacts>
          </collision>
          <collision name='wrist_3_link_fixed_joint_lump__gripper_base_link_collision_2'>
            <pose frame=''>0 0.117 0 3.14159 1.57079 -1.57079</pose>
            <geometry>
              <cylinder>
                <length>0.03</length>
                <radius>0.0375</radius>
              </cylinder>
            </geometry>
            <surface>
              <contact>
                <ode>
                  <kp>1e+08</kp>
                  <kd>1</kd>
                </ode>
              </contact>
              <friction>
                <ode>
                  <mu>100000</mu>
                  <mu2>100000</mu2>
                </ode>
                <torsional>
                  <ode/>
                </torsional>
              </friction>
              <bounce/>
            </surface>
            <max_contacts>10</max_contacts>
          </collision>
          <collision name='wrist_3_link_fixed_joint_lump__camera_link2_collision_3'>
            <pose frame=''>1.6e-05 0.12 -0.08 3.14 0 1.57</pose>
            <geometry>
              <box>
                <size>0.001 0.001 0.001</size>
              </box>
            </geometry>
            <surface>
              <contact>
                <ode/>
              </contact>
              <friction>
                <ode/>
                <torsional>
                  <ode/>
                </torsional>
              </friction>
              <bounce/>
            </surface>
            <max_contacts>10</max_contacts>
          </collision>
          <visual name='wrist_3_link_visual'>
            <pose frame=''>0 0 0 0 -0 0</pose>
            <geometry>
              <mesh>
                <scale>1 1 1</scale>
                <uri>/home/pranshu/ROS_WORKSPACES/Eyantra/src/sahayak_bot/ur_description/meshes/ur5/visual/wrist3.dae</uri>
              </mesh>
            </geometry>
            <material>
              <script>
                <uri>__default__</uri>
                <name>__default__</name>
              </script>
            </material>
          </visual>
          <visual name='wrist_3_link_fixed_joint_lump__gripper_base_link_visual_1'>
            <pose frame=''>0 0.1 0 0 -0 1.5708</pose>
            <geometry>
              <mesh>
                <scale>1 1 1</scale>
                <uri>/home/pranshu/ROS_WORKSPACES/Eyantra/src/sahayak_bot/robotiq_85_gripper-master/robotiq_85_description/meshes/visual/robotiq_85_base_link.dae</uri>
              </mesh>
            </geometry>
            <material>
              <script>
                <uri>__default__</uri>
                <name>__default__</name>
              </script>
            </material>
          </visual>
          <visual name='wrist_3_link_fixed_joint_lump__camera_link2_visual_2'>
            <pose frame=''>0 0.1 -0.08 -1.57089 -0.001593 -0.0007</pose>
            <geometry>
              <mesh>
                <scale>1 1 1</scale>
                <uri>/home/pranshu/ROS_WORKSPACES/Eyantra/src/sahayak_bot/ebot_description/meshes/NAVRS.STL</uri>
              </mesh>
            </geometry>
            <material>
              <script>
                <uri>__default__</uri>
                <name>__default__</name>
              </script>
            </material>
          </visual>
          <velocity_decay/>
          <velocity_decay/>
          <self_collide>1</self_collide>
          <velocity_decay/>
          <gravity>1</gravity>
          <velocity_decay/>
          <sensor name='intelrealsense2' type='depth'>
            <always_on>1</always_on>
            <visualize>1</visualize>
            <camera name='__default__'>
              <horizontal_fov>1.047</horizontal_fov>
              <image>
                <width>640</width>
                <height>480</height>
                <format>R8G8B8</format>
              </image>
              <depth_camera>
                <output>depths</output>
              </depth_camera>
              <clip>
                <near>0.1</near>
                <far>100</far>
              </clip>
            </camera>
            <plugin name='intelrealsense' filename='libgazebo_ros_openni_kinect.so'>
              <alwaysOn>1</alwaysOn>
              <updateRate>10.0</updateRate>
              <cameraName>camera2</cameraName>
              <frameName>camera_depth_frame2</frameName>
              <imageTopicName>/camera/color/image_raw2</imageTopicName>
              <depthImageTopicName>/camera/depth/image_raw2</depthImageTopicName>
              <pointCloudTopicName>depth/points2</pointCloudTopicName>
              <cameraInfoTopicName>/camera/color/camera_info2</cameraInfoTopicName>
              <depthImageCameraInfoTopicName>/camera/depth/camera_info2</depthImageCameraInfoTopicName>
              <pointCloudCutoff>0.2</pointCloudCutoff>
              <pointCloudCutoffMax>10.0</pointCloudCutoffMax>
              <hackBaseline>0.07</hackBaseline>
              <distortionK1>0.0</distortionK1>
              <distortionK2>0.0</distortionK2>
              <distortionK3>0.0</distortionK3>
              <distortionT1>0.0</distortionT1>
              <distortionT2>0.0</distortionT2>
              <CxPrime>0.0</CxPrime>
              <Cx>0.0</Cx>
              <Cy>0.0</Cy>
              <focalLength>0.0</focalLength>
              <robotNamespace>/</robotNamespace>
            </plugin>
            <pose frame=''>0 0.1 -0.08 3.14 0 1.57</pose>
          </sensor>
          <enable_wind>0</enable_wind>
          <kinematic>0</kinematic>
        </link>
        <joint name='wrist_3_joint' type='revolute'>
          <child>wrist_3_link</child>
          <parent>wrist_2_link</parent>
          <axis>
            <xyz>0 1 0</xyz>
            <limit>
              <lower>-6.28319</lower>
              <upper>6.28319</upper>
              <effort>28</effort>
              <velocity>3.2</velocity>
            </limit>
            <dynamics>
              <damping>0</damping>
              <friction>0</friction>
              <spring_reference>0</spring_reference>
              <spring_stiffness>0</spring_stiffness>
            </dynamics>
            <use_parent_model_frame>1</use_parent_model_frame>
          </axis>
        </joint>
        <link name='gripper_finger1_inner_knuckle_link'>
          <pose frame=''>0.303372 0.27057 0.750715 0.523599 -0 1.5708</pose>
          <inertial>
            <pose frame=''>0 0 0 0 -0 0</pose>
            <mass>0.029951</mass>
            <inertia>
              <ixx>3.9e-05</ixx>
              <ixy>0</ixy>
              <ixz>0</ixz>
              <iyy>5e-06</iyy>
              <iyz>0</iyz>
              <izz>3.5e-05</izz>
            </inertia>
          </inertial>
          <collision name='gripper_finger1_inner_knuckle_link_collision'>
            <pose frame=''>0.025 -0.02 0 0 0 -0.698</pose>
            <geometry>
              <box>
                <size>0.055 0.006 0.02</size>
              </box>
            </geometry>
            <surface>
              <contact>
                <ode>
                  <kp>1e+08</kp>
                  <kd>1</kd>
                </ode>
              </contact>
              <friction>
                <ode>
                  <mu>100000</mu>
                  <mu2>100000</mu2>
                </ode>
                <torsional>
                  <ode/>
                </torsional>
              </friction>
              <bounce/>
            </surface>
            <max_contacts>10</max_contacts>
          </collision>
          <visual name='gripper_finger1_inner_knuckle_link_visual'>
            <pose frame=''>0 0 0 0 -0 0</pose>
            <geometry>
              <mesh>
                <scale>1 1 1</scale>
                <uri>/home/pranshu/ROS_WORKSPACES/Eyantra/src/sahayak_bot/robotiq_85_gripper-master/robotiq_85_description/meshes/visual/robotiq_85_inner_knuckle_link.dae</uri>
              </mesh>
            </geometry>
            <material>
              <script>
                <uri>__default__</uri>
                <name>__default__</name>
              </script>
            </material>
          </visual>
          <gravity>1</gravity>
          <velocity_decay/>
          <self_collide>0</self_collide>
          <enable_wind>0</enable_wind>
          <kinematic>0</kinematic>
        </link>
        <joint name='gripper_finger1_inner_knuckle_joint' type='revolute'>
          <child>gripper_finger1_inner_knuckle_link</child>
          <parent>wrist_3_link</parent>
          <axis>
            <xyz>0.5 -0 0.866025</xyz>
            <limit>
              <lower>-1e+16</lower>
              <upper>1e+16</upper>
            </limit>
            <dynamics>
              <spring_reference>0</spring_reference>
              <spring_stiffness>0</spring_stiffness>
            </dynamics>
            <use_parent_model_frame>1</use_parent_model_frame>
          </axis>
        </joint>
        <link name='gripper_finger1_finger_tip_link'>
          <pose frame=''>0.335934 0.31361 0.731915 0.523599 -0 1.5708</pose>
          <inertial>
            <pose frame=''>0 0 0 0 -0 0</pose>
            <mass>0.019555</mass>
            <inertia>
              <ixx>2e-06</ixx>
              <ixy>0</ixy>
              <ixz>0</ixz>
              <iyy>5e-06</iyy>
              <iyz>0</iyz>
              <izz>6e-06</izz>
            </inertia>
          </inertial>
          <collision name='gripper_finger1_finger_tip_link_collision'>
            <pose frame=''>0.02 0 0 0 -0 0</pose>
            <geometry>
              <box>
                <size>0.045 0.01 0.02</size>
              </box>
            </geometry>
            <surface>
              <contact>
                <ode>
                  <kp>1e+08</kp>
                  <kd>1</kd>
                </ode>
              </contact>
              <friction>
                <ode>
                  <mu>100000</mu>
                  <mu2>100000</mu2>
                </ode>
                <torsional>
                  <ode/>
                </torsional>
              </friction>
              <bounce/>
            </surface>
            <max_contacts>10</max_contacts>
          </collision>
          <visual name='gripper_finger1_finger_tip_link_visual'>
            <pose frame=''>0 0 0 0 -0 0</pose>
            <geometry>
              <mesh>
                <scale>1 1 1</scale>
                <uri>/home/pranshu/ROS_WORKSPACES/Eyantra/src/sahayak_bot/robotiq_85_gripper-master/robotiq_85_description/meshes/visual/robotiq_85_finger_tip_link.dae</uri>
              </mesh>
            </geometry>
            <material>
              <script>
                <uri>__default__</uri>
                <name>__default__</name>
              </script>
            </material>
          </visual>
          <gravity>1</gravity>
          <velocity_decay/>
          <self_collide>0</self_collide>
          <enable_wind>0</enable_wind>
          <kinematic>0</kinematic>
        </link>
        <joint name='gripper_finger1_finger_tip_joint' type='revolute'>
          <child>gripper_finger1_finger_tip_link</child>
          <parent>gripper_finger1_inner_knuckle_link</parent>
          <axis>
            <xyz>0.5 -0 0.866025</xyz>
            <limit>
              <lower>-1e+16</lower>
              <upper>1e+16</upper>
            </limit>
            <dynamics>
              <spring_reference>0</spring_reference>
              <spring_stiffness>0</spring_stiffness>
            </dynamics>
            <use_parent_model_frame>1</use_parent_model_frame>
          </axis>
        </joint>
        <link name='gripper_finger1_knuckle_link'>
          <pose frame=''>0.318875 0.264055 0.741764 0.523599 -0 1.5708</pose>
          <inertial>
            <pose frame=''>-0.002436 -0.018774 0 0 -0 0</pose>
            <mass>0.0458</mass>
            <inertia>
              <ixx>2.29304e-05</ixx>
              <ixy>-4.4183e-06</ixy>
              <ixz>0</ixz>
              <iyy>2.2184e-05</iyy>
              <iyz>0</iyz>
              <izz>4.11145e-05</izz>
            </inertia>
          </inertial>
          <collision name='gripper_finger1_knuckle_link_collision'>
            <pose frame=''>0 -0.01 0 0 0 -0.0873</pose>
            <geometry>
              <box>
                <size>0.012 0.035 0.014</size>
              </box>
            </geometry>
            <surface>
              <contact>
                <ode>
                  <kp>1e+08</kp>
                  <kd>1</kd>
                </ode>
              </contact>
              <friction>
                <ode>
                  <mu>100000</mu>
                  <mu2>100000</mu2>
                </ode>
                <torsional>
                  <ode/>
                </torsional>
              </friction>
              <bounce/>
            </surface>
            <max_contacts>10</max_contacts>
          </collision>
          <collision name='gripper_finger1_knuckle_link_fixed_joint_lump__gripper_finger1_finger_link_collision_1'>
            <pose frame=''>0.020915 -0.033486 0 0 0 -0.175</pose>
            <geometry>
              <box>
                <size>0.0591 0.01 0.02</size>
              </box>
            </geometry>
            <surface>
              <contact>
                <ode>
                  <kp>1e+08</kp>
                  <kd>1</kd>
                </ode>
              </contact>
              <friction>
                <ode>
                  <mu>100000</mu>
                  <mu2>100000</mu2>
                </ode>
                <torsional>
                  <ode/>
                </torsional>
              </friction>
              <bounce/>
            </surface>
            <max_contacts>10</max_contacts>
          </collision>
          <visual name='gripper_finger1_knuckle_link_visual'>
            <pose frame=''>0 0 0 0 -0 0</pose>
            <geometry>
              <mesh>
                <scale>1 1 1</scale>
                <uri>/home/pranshu/ROS_WORKSPACES/Eyantra/src/sahayak_bot/robotiq_85_gripper-master/robotiq_85_description/meshes/visual/robotiq_85_knuckle_link.dae</uri>
              </mesh>
            </geometry>
            <material>
              <script>
                <uri>__default__</uri>
                <name>__default__</name>
              </script>
            </material>
          </visual>
          <visual name='gripper_finger1_knuckle_link_fixed_joint_lump__gripper_finger1_finger_link_visual_1'>
            <pose frame=''>-0.004086 -0.031486 0 0 -0 0</pose>
            <geometry>
              <mesh>
                <scale>1 1 1</scale>
                <uri>/home/pranshu/ROS_WORKSPACES/Eyantra/src/sahayak_bot/robotiq_85_gripper-master/robotiq_85_description/meshes/visual/robotiq_85_finger_link.dae</uri>
              </mesh>
            </geometry>
            <material>
              <script>
                <uri>__default__</uri>
                <name>__default__</name>
              </script>
            </material>
          </visual>
          <velocity_decay/>
          <gravity>1</gravity>
          <velocity_decay/>
          <self_collide>0</self_collide>
          <enable_wind>0</enable_wind>
          <kinematic>0</kinematic>
        </link>
        <joint name='gripper_finger1_joint' type='revolute'>
          <child>gripper_finger1_knuckle_link</child>
          <parent>wrist_3_link</parent>
          <axis>
            <xyz>0.5 -0 0.866025</xyz>
            <limit>
              <lower>0</lower>
              <upper>0.804</upper>
              <effort>1000</effort>
              <velocity>2</velocity>
            </limit>
            <dynamics>
              <spring_reference>0</spring_reference>
              <spring_stiffness>0</spring_stiffness>
            </dynamics>
            <use_parent_model_frame>1</use_parent_model_frame>
          </axis>
        </joint>
        <link name='gripper_finger2_inner_knuckle_link'>
          <pose frame=''>0.281375 0.27057 0.763415 -2.61799 0 1.5708</pose>
          <inertial>
            <pose frame=''>0 0 0 0 -0 0</pose>
            <mass>0.029951</mass>
            <inertia>
              <ixx>3.9e-05</ixx>
              <ixy>0</ixy>
              <ixz>0</ixz>
              <iyy>5e-06</iyy>
              <iyz>0</iyz>
              <izz>3.5e-05</izz>
            </inertia>
          </inertial>
          <collision name='gripper_finger2_inner_knuckle_link_collision'>
            <pose frame=''>0.025 -0.02 0 0 0 -0.698</pose>
            <geometry>
              <box>
                <size>0.055 0.006 0.02</size>
              </box>
            </geometry>
            <surface>
              <contact>
                <ode>
                  <kp>1e+08</kp>
                  <kd>1</kd>
                </ode>
              </contact>
              <friction>
                <ode>
                  <mu>100000</mu>
                  <mu2>100000</mu2>
                </ode>
                <torsional>
                  <ode/>
                </torsional>
              </friction>
              <bounce/>
            </surface>
            <max_contacts>10</max_contacts>
          </collision>
          <visual name='gripper_finger2_inner_knuckle_link_visual'>
            <pose frame=''>0 0 0 0 -0 0</pose>
            <geometry>
              <mesh>
                <scale>1 1 1</scale>
                <uri>/home/pranshu/ROS_WORKSPACES/Eyantra/src/sahayak_bot/robotiq_85_gripper-master/robotiq_85_description/meshes/visual/robotiq_85_inner_knuckle_link.dae</uri>
              </mesh>
            </geometry>
            <material>
              <script>
                <uri>__default__</uri>
                <name>__default__</name>
              </script>
            </material>
          </visual>
          <gravity>1</gravity>
          <velocity_decay/>
          <self_collide>0</self_collide>
          <enable_wind>0</enable_wind>
          <kinematic>0</kinematic>
        </link>
        <joint name='gripper_finger2_inner_knuckle_joint' type='revolute'>
          <child>gripper_finger2_inner_knuckle_link</child>
          <parent>wrist_3_link</parent>
          <axis>
            <xyz>-0.5 0 -0.866025</xyz>
            <limit>
              <lower>-1e+16</lower>
              <upper>1e+16</upper>
            </limit>
            <dynamics>
              <spring_reference>0</spring_reference>
              <spring_stiffness>0</spring_stiffness>
            </dynamics>
            <use_parent_model_frame>1</use_parent_model_frame>
          </axis>
        </joint>
        <link name='gripper_finger2_finger_tip_link'>
          <pose frame=''>0.248813 0.31361 0.782214 -2.61799 0 1.5708</pose>
          <inertial>
            <pose frame=''>0 0 0 0 -0 0</pose>
            <mass>0.019555</mass>
            <inertia>
              <ixx>2e-06</ixx>
              <ixy>0</ixy>
              <ixz>0</ixz>
              <iyy>5e-06</iyy>
              <iyz>0</iyz>
              <izz>6e-06</izz>
            </inertia>
          </inertial>
          <collision name='gripper_finger2_finger_tip_link_collision'>
            <pose frame=''>0.02 0 0 0 -0 0</pose>
            <geometry>
              <box>
                <size>0.045 0.01 0.02</size>
              </box>
            </geometry>
            <surface>
              <contact>
                <ode>
                  <kp>1e+08</kp>
                  <kd>1</kd>
                </ode>
              </contact>
              <friction>
                <ode>
                  <mu>100000</mu>
                  <mu2>100000</mu2>
                </ode>
                <torsional>
                  <ode/>
                </torsional>
              </friction>
              <bounce/>
            </surface>
            <max_contacts>10</max_contacts>
          </collision>
          <visual name='gripper_finger2_finger_tip_link_visual'>
            <pose frame=''>0 0 0 0 -0 0</pose>
            <geometry>
              <mesh>
                <scale>1 1 1</scale>
                <uri>/home/pranshu/ROS_WORKSPACES/Eyantra/src/sahayak_bot/robotiq_85_gripper-master/robotiq_85_description/meshes/visual/robotiq_85_finger_tip_link.dae</uri>
              </mesh>
            </geometry>
            <material>
              <script>
                <uri>__default__</uri>
                <name>__default__</name>
              </script>
            </material>
          </visual>
          <gravity>1</gravity>
          <velocity_decay/>
          <self_collide>0</self_collide>
          <enable_wind>0</enable_wind>
          <kinematic>0</kinematic>
        </link>
        <joint name='gripper_finger2_finger_tip_joint' type='revolute'>
          <child>gripper_finger2_finger_tip_link</child>
          <parent>gripper_finger2_inner_knuckle_link</parent>
          <axis>
            <xyz>-0.5 0 -0.866025</xyz>
            <limit>
              <lower>-1e+16</lower>
              <upper>1e+16</upper>
            </limit>
            <dynamics>
              <spring_reference>0</spring_reference>
              <spring_stiffness>0</spring_stiffness>
            </dynamics>
            <use_parent_model_frame>1</use_parent_model_frame>
          </axis>
        </joint>
        <link name='gripper_finger2_knuckle_link'>
          <pose frame=''>0.265872 0.264055 0.772365 -2.61799 0 1.5708</pose>
          <inertial>
            <pose frame=''>-0.002436 -0.018774 0 0 -0 0</pose>
            <mass>0.0458</mass>
            <inertia>
              <ixx>2.29304e-05</ixx>
              <ixy>-4.4183e-06</ixy>
              <ixz>0</ixz>
              <iyy>2.2184e-05</iyy>
              <iyz>0</iyz>
              <izz>4.11145e-05</izz>
            </inertia>
          </inertial>
          <collision name='gripper_finger2_knuckle_link_collision'>
            <pose frame=''>0 -0.01 0 0 0 -0.0873</pose>
            <geometry>
              <box>
                <size>0.012 0.035 0.014</size>
              </box>
            </geometry>
            <surface>
              <contact>
                <ode>
                  <kp>1e+08</kp>
                  <kd>1</kd>
                </ode>
              </contact>
              <friction>
                <ode>
                  <mu>100000</mu>
                  <mu2>100000</mu2>
                </ode>
                <torsional>
                  <ode/>
                </torsional>
              </friction>
              <bounce/>
            </surface>
            <max_contacts>10</max_contacts>
          </collision>
          <collision name='gripper_finger2_knuckle_link_fixed_joint_lump__gripper_finger2_finger_link_collision_1'>
            <pose frame=''>0.020915 -0.033486 0 0 0 -0.175</pose>
            <geometry>
              <box>
                <size>0.0591 0.01 0.02</size>
              </box>
            </geometry>
            <surface>
              <contact>
                <ode>
                  <kp>1e+08</kp>
                  <kd>1</kd>
                </ode>
              </contact>
              <friction>
                <ode>
                  <mu>100000</mu>
                  <mu2>100000</mu2>
                </ode>
                <torsional>
                  <ode/>
                </torsional>
              </friction>
              <bounce/>
            </surface>
            <max_contacts>10</max_contacts>
          </collision>
          <visual name='gripper_finger2_knuckle_link_visual'>
            <pose frame=''>0 0 0 0 -0 0</pose>
            <geometry>
              <mesh>
                <scale>1 1 1</scale>
                <uri>/home/pranshu/ROS_WORKSPACES/Eyantra/src/sahayak_bot/robotiq_85_gripper-master/robotiq_85_description/meshes/visual/robotiq_85_knuckle_link.dae</uri>
              </mesh>
            </geometry>
            <material>
              <script>
                <uri>__default__</uri>
                <name>__default__</name>
              </script>
            </material>
          </visual>
          <visual name='gripper_finger2_knuckle_link_fixed_joint_lump__gripper_finger2_finger_link_visual_1'>
            <pose frame=''>-0.004086 -0.031486 0 0 -0 0</pose>
            <geometry>
              <mesh>
                <scale>1 1 1</scale>
                <uri>/home/pranshu/ROS_WORKSPACES/Eyantra/src/sahayak_bot/robotiq_85_gripper-master/robotiq_85_description/meshes/visual/robotiq_85_finger_link.dae</uri>
              </mesh>
            </geometry>
            <material>
              <script>
                <uri>__default__</uri>
                <name>__default__</name>
              </script>
            </material>
          </visual>
          <velocity_decay/>
          <gravity>1</gravity>
          <velocity_decay/>
          <self_collide>0</self_collide>
          <enable_wind>0</enable_wind>
          <kinematic>0</kinematic>
        </link>
        <joint name='gripper_finger2_joint' type='revolute'>
          <child>gripper_finger2_knuckle_link</child>
          <parent>wrist_3_link</parent>
          <axis>
            <xyz>-0.5 0 -0.866025</xyz>
            <limit>
              <lower>-3.14</lower>
              <upper>3.14</upper>
              <effort>1000</effort>
              <velocity>100</velocity>
            </limit>
            <dynamics>
              <spring_reference>0</spring_reference>
              <spring_stiffness>0</spring_stiffness>
            </dynamics>
            <use_parent_model_frame>1</use_parent_model_frame>
          </axis>
        </joint>
        <plugin name='skid_steer_drive_controller' filename='libgazebo_ros_skid_steer_drive.so'>
          <updateRate>40.0</updateRate>
          <leftFrontJoint>FWLJ</leftFrontJoint>
          <rightFrontJoint>FWRJ</rightFrontJoint>
          <leftRearJoint>RWLJ</leftRearJoint>
          <rightRearJoint>RWRJ</rightRearJoint>
          <wheelSeparation>0.4</wheelSeparation>
          <wheelDiameter>0.2</wheelDiameter>
          <robotBaseFrame>ebot_base</robotBaseFrame>
          <torque>60</torque>
          <topicName>cmd_vel</topicName>
          <commandTopic>cmd_vel</commandTopic>
          <odometryTopic>odom</odometryTopic>
          <odometryFrame>odom</odometryFrame>
          <broadcastTF>1</broadcastTF>
          <robotNamespace>/</robotNamespace>
        </plugin>
        <plugin name='ros_control' filename='libgazebo_ros_control.so'>
          <robotNamespace>/</robotNamespace>
        </plugin>
        <plugin name='gazebo_grasp_fix' filename='libgazebo_grasp_fix.so'>
          <arm>
            <arm_name>gripper_arm</arm_name>
            <palm_link>wrist_3_link</palm_link>
            <gripper_link>gripper_finger1_finger_tip_link</gripper_link>
            <gripper_link>gripper_finger2_finger_tip_link</gripper_link>
          </arm>
          <forces_angle_tolerance>100</forces_angle_tolerance>
          <update_rate>2</update_rate>
          <grip_count_threshold>1</grip_count_threshold>
          <max_grip_count>2</max_grip_count>
          <release_tolerance>0.005</release_tolerance>
          <disable_collisions_on_attach>1</disable_collisions_on_attach>
          <contact_topic>__default_topic__</contact_topic>
          <robotNamespace>/</robotNamespace>
        </plugin>
        <static>0</static>
        <plugin name='mimic_robotiq_85_1' filename='libroboticsgroup_gazebo_mimic_joint_plugin.so'>
          <joint>gripper_finger1_joint</joint>
          <mimicJoint>gripper_finger2_joint</mimicJoint>
          <robotNamespace>/</robotNamespace>
        </plugin>
        <plugin name='mimic_robotiq_85_2' filename='libroboticsgroup_gazebo_mimic_joint_plugin.so'>
          <joint>gripper_finger1_joint</joint>
          <mimicJoint>gripper_finger2_inner_knuckle_joint</mimicJoint>
          <robotNamespace>/</robotNamespace>
        </plugin>
        <plugin name='mimic_robotiq_85_3' filename='libroboticsgroup_gazebo_mimic_joint_plugin.so'>
          <joint>gripper_finger1_joint</joint>
          <mimicJoint>gripper_finger1_inner_knuckle_joint</mimicJoint>
          <robotNamespace>/</robotNamespace>
        </plugin>
        <plugin name='mimic_robotiq_85_4' filename='libroboticsgroup_gazebo_mimic_joint_plugin.so'>
          <joint>gripper_finger1_joint</joint>
          <mimicJoint>gripper_finger1_finger_tip_joint</mimicJoint>
          <multiplier>-1.0</multiplier>
          <offset>0.0</offset>
          <robotNamespace>/</robotNamespace>
        </plugin>
        <plugin name='mimic_robotiq_85_5' filename='libroboticsgroup_gazebo_mimic_joint_plugin.so'>
          <joint>gripper_finger1_joint</joint>
          <mimicJoint>gripper_finger2_finger_tip_joint</mimicJoint>
          <multiplier>-1.0</multiplier>
          <offset>0.0</offset>
          <robotNamespace>/</robotNamespace>
        </plugin>
        <pose frame=''>0 0 0 0 -0 0</pose>
      </model>
      <model name='coke_can'>
        <link name='link'>
          <inertial>
            <pose frame=''>0 0 0.06 0 -0 0</pose>
            <mass>0.39</mass>
            <inertia>
              <ixx>0.00055575</ixx>
              <ixy>0</ixy>
              <ixz>0</ixz>
              <iyy>0.00055575</iyy>
              <iyz>0</iyz>
              <izz>0.0001755</izz>
            </inertia>
          </inertial>
          <collision name='collision'>
            <pose frame=''>0.003937 0.004724 -0.18 0 -0 0</pose>
            <geometry>
              <mesh>
                <uri>model://coke_can/meshes/coke_can.dae</uri>
              </mesh>
            </geometry>
            <surface>
              <friction>
                <ode>
                  <mu>1</mu>
                  <mu2>1</mu2>
                </ode>
                <torsional>
                  <ode/>
                </torsional>
              </friction>
              <contact>
                <ode>
                  <kp>1e+07</kp>
                  <kd>1</kd>
                  <min_depth>0.001</min_depth>
                  <max_vel>0.1</max_vel>
                </ode>
              </contact>
              <bounce/>
            </surface>
            <max_contacts>10</max_contacts>
          </collision>
          <visual name='visual'>
            <pose frame=''>0.003937 0.004724 -0.18 0 -0 0</pose>
            <geometry>
              <mesh>
                <uri>model://coke_can/meshes/coke_can.dae</uri>
              </mesh>
            </geometry>
          </visual>
          <self_collide>0</self_collide>
          <enable_wind>0</enable_wind>
          <kinematic>0</kinematic>
        </link>
        <pose frame=''>15.23 -1.045 0.87 0 -0 0</pose>
      </model>
      <model name='water_glass'>
        <link name='link'>
          <inertial>
            <pose frame=''>0 0 0 0 -0 0</pose>
            <mass>0.8</mass>
            <inertia>
              <ixx>1</ixx>
              <ixy>0</ixy>
              <ixz>0</ixz>
              <iyy>1</iyy>
              <iyz>0</iyz>
              <izz>1</izz>
            </inertia>
          </inertial>
          <collision name='colision1'>
            <pose frame=''>0 0 0 0 -0 0</pose>
            <geometry>
              <mesh>
                <uri>model://water_glass/meshes/glass.dae</uri>
              </mesh>
            </geometry>
            <max_contacts>10</max_contacts>
            <surface>
              <contact>
                <ode/>
              </contact>
              <bounce/>
              <friction>
                <torsional>
                  <ode/>
                </torsional>
                <ode/>
              </friction>
            </surface>
          </collision>
          <visual name='visual1'>
            <cast_shadows>0</cast_shadows>
            <pose frame=''>0 0 0 0 -0 0</pose>
            <geometry>
              <mesh>
                <uri>model://water_glass/meshes/glass.dae</uri>
              </mesh>
            </geometry>
            <material>
              <script>
                <name>Gazebo/GreyTransparent</name>
                <uri>file://media/materials/scripts/gazebo.material</uri>
              </script>
            </material>
          </visual>
          <self_collide>0</self_collide>
          <enable_wind>0</enable_wind>
          <kinematic>0</kinematic>
        </link>
        <pose frame=''>10.72 -0.86 0.87 0 -0 0</pose>
      </model>
      <model name='adhesive'>
        <link name='link'>
          <inertial>
            <pose frame=''>0 0 0 0 -0 0</pose>
            <mass>0.08</mass>
            <inertia>
              <ixx>1</ixx>
              <ixy>0</ixy>
              <ixz>0</ixz>
              <iyy>1</iyy>
              <iyz>0</iyz>
              <izz>1</izz>
            </inertia>
          </inertial>
          <collision name='colision1'>
            <pose frame=''>0 0 0 0 -0 0</pose>
            <geometry>
              <mesh>
                <uri>model://adhesive/meshes/adhesive.dae</uri>
              </mesh>
            </geometry>
            <max_contacts>10</max_contacts>
            <surface>
              <contact>
                <ode/>
              </contact>
              <bounce/>
              <friction>
                <torsional>
                  <ode/>
                </torsional>
                <ode/>
              </friction>
            </surface>
          </collision>
          <visual name='visual1'>
            <cast_shadows>0</cast_shadows>
            <pose frame=''>0 0 0 0 -0 0</pose>
            <geometry>
              <mesh>
                <uri>model://adhesive/meshes/adhesive.dae</uri>
              </mesh>
            </geometry>
            <material>
              <script>
                <name>Gazebo/White</name>
                <uri>file://media/materials/scripts/gazebo.material</uri>
              </script>
            </material>
          </visual>
          <self_collide>0</self_collide>
          <enable_wind>0</enable_wind>
          <kinematic>0</kinematic>
        </link>
        <pose frame=''>26.7 -2.984 1.17 0 -0 1.57</pose>
      </model>
      <model name='glue'>
        <link name='glue_link'>
          <inertial>
            <pose frame=''>0 0 0 0 -0 0</pose>
            <mass>0.08</mass>
            <inertia>
              <ixx>1</ixx>
              <ixy>0</ixy>
              <ixz>0</ixz>
              <iyy>1</iyy>
              <iyz>0</iyz>
              <izz>1</izz>
            </inertia>
          </inertial>
          <visual name='glue_visual'>
            <pose frame=''>0 0 0 0 -0 0</pose>
            <material>
              <script>
                <uri>model://glue/materials/scripts</uri>
                <uri>model://glue/materials/textures</uri>
                <name>glue</name>
              </script>
            </material>
            <geometry>
              <mesh>
                <uri>model://glue/meshes/glue.dae</uri>
              </mesh>
            </geometry>
          </visual>
          <collision name='glue_collision'>
            <pose frame=''>0 0.001 0.067 0 0 -0.95</pose>
            <geometry>
              <box>
                <size>0.06 0.032 0.133</size>
              </box>
            </geometry>
            <max_contacts>10</max_contacts>
            <surface>
              <contact>
                <ode/>
              </contact>
              <bounce/>
              <friction>
                <torsional>
                  <ode/>
                </torsional>
                <ode/>
              </friction>
            </surface>
          </collision>
          <self_collide>0</self_collide>
          <enable_wind>0</enable_wind>
          <kinematic>0</kinematic>
        </link>
        <pose frame=''>26.29 -3.613 1.17 0 -0 3.14</pose>
      </model>
      <model name='battery'>
        <link name='soap2_link'>
          <inertial>
            <pose frame=''>0 0 0 0 -0 0</pose>
            <mass>0.08</mass>
            <inertia>
              <ixx>1</ixx>
              <ixy>0</ixy>
              <ixz>0</ixz>
              <iyy>1</iyy>
              <iyz>0</iyz>
              <izz>1</izz>
            </inertia>
          </inertial>
          <visual name='soap2_visual'>
            <pose frame=''>0 0 0 0 -0 0</pose>
            <material>
              <script>
                <uri>model://soap2/materials/scripts</uri>
                <uri>model://soap2/materials/textures</uri>
                <name>soap2</name>
              </script>
            </material>
            <geometry>
              <mesh>
                <uri>model://soap2/meshes/soap2.dae</uri>
              </mesh>
            </geometry>
          </visual>
          <collision name='soap2_collision'>
            <pose frame=''>-0.002 0.00502 0.05 0 0 -1</pose>
            <geometry>
              <box>
                <size>0.065 0.04 0.105</size>
              </box>
            </geometry>
            <max_contacts>10</max_contacts>
            <surface>
              <contact>
                <ode/>
              </contact>
              <bounce/>
              <friction>
                <torsional>
                  <ode/>
                </torsional>
                <ode/>
              </friction>
            </surface>
          </collision>
          <self_collide>0</self_collide>
          <enable_wind>0</enable_wind>
          <kinematic>0</kinematic>
        </link>
        <pose frame=''>26.55 -3.23 1.17 0 -0 0.524</pose>
      </model>
      <model name='FPGA_board'>
        <link name='soap_link'>
          <inertial>
            <pose frame=''>0 0 0 0 -0 0</pose>
            <mass>0.08</mass>
            <inertia>
              <ixx>1</ixx>
              <ixy>0</ixy>
              <ixz>0</ixz>
              <iyy>1</iyy>
              <iyz>0</iyz>
              <izz>1</izz>
            </inertia>
          </inertial>
          <visual name='soap_visual'>
            <pose frame=''>0 0 0 0 -0 0</pose>
            <material>
              <script>
                <uri>model://soap/materials/scripts</uri>
                <uri>model://soap/materials/textures</uri>
                <name>soap</name>
              </script>
            </material>
            <geometry>
              <mesh>
                <uri>model://soap/meshes/soap.dae</uri>
              </mesh>
            </geometry>
          </visual>
          <collision name='soap_collision'>
            <pose frame=''>0.02 0.002 0.05 0 0 -1.05</pose>
            <geometry>
              <box>
                <size>0.14 0.065 0.1</size>
              </box>
            </geometry>
            <max_contacts>10</max_contacts>
            <surface>
              <contact>
                <ode/>
              </contact>
              <bounce/>
              <friction>
                <torsional>
                  <ode/>
                </torsional>
                <ode/>
              </friction>
            </surface>
          </collision>
          <self_collide>0</self_collide>
          <enable_wind>0</enable_wind>
          <kinematic>0</kinematic>
        </link>
        <pose frame=''>26.78 -3.21 1.17 0 -0 0.785</pose>
      </model>
      <model name='robot_wheels'>
        <link name='link'>
          <collision name='colision1'>
            <pose frame=''>0 0 0 0 -0 0</pose>
            <geometry>
              <mesh>
                <uri>model://robot_wheels/meshes/robot_wheels.dae</uri>
              </mesh>
            </geometry>
            <max_contacts>10</max_contacts>
            <surface>
              <contact>
                <ode/>
              </contact>
              <bounce/>
              <friction>
                <torsional>
                  <ode/>
                </torsional>
                <ode/>
              </friction>
            </surface>
          </collision>
          <visual name='visual1'>
            <cast_shadows>0</cast_shadows>
            <pose frame=''>0 0 0 0 -0 0</pose>
            <geometry>
              <mesh>
                <uri>model://robot_wheels/meshes/robot_wheels.dae</uri>
              </mesh>
            </geometry>
          </visual>
          <self_collide>0</self_collide>
          <inertial>
            <inertia>
              <ixx>1</ixx>
              <ixy>0</ixy>
              <ixz>0</ixz>
              <iyy>1</iyy>
              <iyz>0</iyz>
              <izz>1</izz>
            </inertia>
            <mass>1</mass>
          </inertial>
          <enable_wind>0</enable_wind>
          <kinematic>0</kinematic>
        </link>
        <pose frame=''>26.395 -3.45 1.17 0 -0 0</pose>
      </model>
      <model name='eYFi_board'>
        <static>0</static>
        <link name='link'>
          <collision name='colision1'>
            <pose frame=''>0 0 0 0 -0 0</pose>
            <geometry>
              <mesh>
                <uri>model://eYIFI/meshes/eyifi.obj</uri>
              </mesh>
            </geometry>
            <max_contacts>10</max_contacts>
            <surface>
              <contact>
                <ode/>
              </contact>
              <bounce/>
              <friction>
                <torsional>
                  <ode/>
                </torsional>
                <ode/>
              </friction>
            </surface>
          </collision>
          <visual name='visual1'>
            <cast_shadows>0</cast_shadows>
            <pose frame=''>0 0 0 0 -0 0</pose>
            <geometry>
              <mesh>
                <uri>model://eYIFI/meshes/eyifi.obj</uri>
              </mesh>
            </geometry>
          </visual>
          <self_collide>0</self_collide>
          <inertial>
            <inertia>
              <ixx>1</ixx>
              <ixy>0</ixy>
              <ixz>0</ixz>
              <iyy>1</iyy>
              <iyz>0</iyz>
              <izz>1</izz>
            </inertia>
            <mass>1</mass>
          </inertial>
          <enable_wind>0</enable_wind>
          <kinematic>0</kinematic>
        </link>
        <pose frame=''>26.33 -3.88 1.17 0 -0 2.094</pose>
      </model>
      <model name='battery2'>
        <link name='soap2_link'>
          <inertial>
            <pose frame=''>0 0 0 0 -0 0</pose>
            <mass>0.08</mass>
            <inertia>
              <ixx>1</ixx>
              <ixy>0</ixy>
              <ixz>0</ixz>
              <iyy>1</iyy>
              <iyz>0</iyz>
              <izz>1</izz>
            </inertia>
          </inertial>
          <visual name='soap2_visual'>
            <pose frame=''>0 0 0 0 -0 0</pose>
            <material>
              <script>
                <uri>model://soap2/materials/scripts</uri>
                <uri>model://soap2/materials/textures</uri>
                <name>soap2</name>
              </script>
            </material>
            <geometry>
              <mesh>
                <uri>model://soap2/meshes/soap2.dae</uri>
              </mesh>
            </geometry>
          </visual>
          <collision name='soap2_collision'>
            <pose frame=''>-0.002 0.00502 0.05 0 0 -1</pose>
            <geometry>
              <box>
                <size>0.065 0.04 0.105</size>
              </box>
            </geometry>
            <max_contacts>10</max_contacts>
            <surface>
              <contact>
                <ode/>
              </contact>
              <bounce/>
              <friction>
                <torsional>
                  <ode/>
                </torsional>
                <ode/>
              </friction>
            </surface>
          </collision>
          <self_collide>0</self_collide>
          <enable_wind>0</enable_wind>
          <kinematic>0</kinematic>
        </link>
        <pose frame=''>5.66 4.36 1.025 0 -0 3.14</pose>
      </model>
      <model name='glue2'>
        <link name='glue_link'>
          <inertial>
            <pose frame=''>0 0 0 0 -0 0</pose>
            <mass>0.08</mass>
            <inertia>
              <ixx>1</ixx>
              <ixy>0</ixy>
              <ixz>0</ixz>
              <iyy>1</iyy>
              <iyz>0</iyz>
              <izz>1</izz>
            </inertia>
          </inertial>
          <visual name='glue_visual'>
            <pose frame=''>0 0 0 0 -0 0</pose>
            <material>
              <script>
                <uri>model://glue/materials/scripts</uri>
                <uri>model://glue/materials/textures</uri>
                <name>glue</name>
              </script>
            </material>
            <geometry>
              <mesh>
                <uri>model://glue/meshes/glue.dae</uri>
              </mesh>
            </geometry>
          </visual>
          <collision name='glue_collision'>
            <pose frame=''>0 0.001 0.067 0 0 -0.95</pose>
            <geometry>
              <box>
                <size>0.06 0.032 0.133</size>
              </box>
            </geometry>
            <max_contacts>10</max_contacts>
            <surface>
              <contact>
                <ode/>
              </contact>
              <bounce/>
              <friction>
                <torsional>
                  <ode/>
                </torsional>
                <ode/>
              </friction>
            </surface>
          </collision>
          <self_collide>0</self_collide>
          <enable_wind>0</enable_wind>
          <kinematic>0</kinematic>
        </link>
        <pose frame=''>5.31 4.3 1.025 0 -0 1.053</pose>
      </model>
      <model name='adhesive2'>
        <link name='link'>
          <inertial>
            <pose frame=''>0 0 0 0 -0 0</pose>
            <mass>0.08</mass>
            <inertia>
              <ixx>1</ixx>
              <ixy>0</ixy>
              <ixz>0</ixz>
              <iyy>1</iyy>
              <iyz>0</iyz>
              <izz>1</izz>
            </inertia>
          </inertial>
          <collision name='colision1'>
            <pose frame=''>0 0 0 0 -0 0</pose>
            <geometry>
              <mesh>
                <uri>model://adhesive/meshes/adhesive.dae</uri>
              </mesh>
            </geometry>
            <max_contacts>10</max_contacts>
            <surface>
              <contact>
                <ode/>
              </contact>
              <bounce/>
              <friction>
                <torsional>
                  <ode/>
                </torsional>
                <ode/>
              </friction>
            </surface>
          </collision>
          <visual name='visual1'>
            <cast_shadows>0</cast_shadows>
            <pose frame=''>0 0 0 0 -0 0</pose>
            <geometry>
              <mesh>
                <uri>model://adhesive/meshes/adhesive.dae</uri>
              </mesh>
            </geometry>
            <material>
              <script>
                <name>Gazebo/White</name>
                <uri>file://media/materials/scripts/gazebo.material</uri>
              </script>
            </material>
          </visual>
          <self_collide>0</self_collide>
          <enable_wind>0</enable_wind>
          <kinematic>0</kinematic>
        </link>
        <pose frame=''>5.47 4.2 1.025 0 -0 1.57</pose>
      </model>
      <state world_name='default'>
        <sim_time>27 229000000</sim_time>
        <real_time>54 673587610</real_time>
        <wall_time>1615958197 59573708</wall_time>
        <iterations>27229</iterations>
        <model name='DropBox1'>
          <pose frame=''>5.61 -1.16 0.87 0 -0 0</pose>
          <scale>1 1 1</scale>
          <link name='link_0'>
            <pose frame=''>5.61 -1.16 0.87 0 0 -1.56873</pose>
            <velocity>0 0 0 0 -0 0</velocity>
            <acceleration>0 0 0 0 -0 0</acceleration>
            <wrench>0 0 0 0 -0 0</wrench>
          </link>
        </model>
        <model name='DropBox2'>
          <pose frame=''>6.99 3.37 0.87 0 -0 0</pose>
          <scale>1 1 1</scale>
          <link name='link_0'>
            <pose frame=''>6.99 3.37 0.87 0 0 -1.56873</pose>
            <velocity>0 0 0 0 -0 0</velocity>
            <acceleration>0 0 0 0 -0 0</acceleration>
            <wrench>0 0 0 0 -0 0</wrench>
          </link>
        </model>
        <model name='DropBox3'>
          <pose frame=''>11.64 9.51 0.87 0 -0 0</pose>
          <scale>1 1 1</scale>
          <link name='link_0'>
            <pose frame=''>11.64 9.51 0.87 0 0 -1.56873</pose>
            <velocity>0 0 0 0 -0 0</velocity>
            <acceleration>0 0 0 0 -0 0</acceleration>
            <wrench>0 0 0 0 -0 0</wrench>
          </link>
        </model>
        <model name='FPGA_board'>
          <pose frame=''>26.78 -3.21 1.01504 -0.00059 -0.00034 0.785</pose>
          <scale>1 1 1</scale>
          <link name='soap_link'>
            <pose frame=''>26.78 -3.21 1.01504 -0.00059 -0.00034 0.785</pose>
            <velocity>0 0 0 0 -0 0</velocity>
            <acceleration>2e-06 -0 -0.003149 0.001975 0.049638 0</acceleration>
            <wrench>0 -0 -0.000252 0 -0 0</wrench>
          </link>
        </model>
        <model name='adhesive'>
          <pose frame=''>26.7 -2.984 1.17 4e-06 -5e-06 1.57</pose>
          <scale>1 1 1</scale>
          <link name='link'>
            <pose frame=''>26.7 -2.984 1.17 4e-06 -5e-06 1.57</pose>
            <velocity>0 0 0 0 -0 0</velocity>
            <acceleration>0 0 -9.8 0 -0 0</acceleration>
            <wrench>0 0 -0.784 0 -0 0</wrench>
          </link>
        </model>
        <model name='adhesive2'>
          <pose frame=''>5.47 4.19999 1.02549 6e-06 -4.8e-05 1.57</pose>
          <scale>1 1 1</scale>
          <link name='link'>
            <pose frame=''>5.47 4.19999 1.02549 6e-06 -4.8e-05 1.57</pose>
            <velocity>0 0 0 0 -0 0</velocity>
            <acceleration>-0.001876 0.00702 19.5727 -0.0453 -0.012102 0</acceleration>
            <wrench>-0.00015 0.000562 1.56582 0 -0 0</wrench>
          </link>
        </model>
        <model name='battery'>
          <pose frame=''>26.55 -3.23 1.01752 0.000432 0.000363 0.524</pose>
          <scale>1 1 1</scale>
          <link name='soap2_link'>
            <pose frame=''>26.55 -3.23 1.01752 0.000432 0.000363 0.524</pose>
            <velocity>0 0 0 0 -0 0</velocity>
            <acceleration>-6.7e-05 -1.2e-05 -0.000926 0.004884 -0.026502 -0</acceleration>
            <wrench>-5e-06 -1e-06 -7.4e-05 0 -0 0</wrench>
          </link>
        </model>
        <model name='battery2'>
          <pose frame=''>5.66 4.36 0.87299 0.000277 7.7e-05 3.14</pose>
          <scale>1 1 1</scale>
          <link name='soap2_link'>
            <pose frame=''>5.66 4.36 0.87299 0.000277 7.7e-05 3.14</pose>
            <velocity>0 0 0 0 -0 0</velocity>
            <acceleration>0 0 -9.8 0 -0 0</acceleration>
            <wrench>0 0 -0.784 0 -0 0</wrench>
          </link>
        </model>
        <model name='coke_can'>
          <pose frame=''>15.23 -1.04507 0.867748 -0.028605 0.000653 3.3e-05</pose>
          <scale>1 1 1</scale>
          <link name='link'>
            <pose frame=''>15.23 -1.04507 0.867748 -0.028605 0.000653 3.3e-05</pose>
            <velocity>0 0 0 0 -0 0</velocity>
            <acceleration>-2.8e-05 1.1e-05 -3e-06 -0.000195 -0.000484 -3.4e-05</acceleration>
            <wrench>-1.1e-05 4e-06 -1e-06 0 -0 0</wrench>
          </link>
        </model>
        <model name='eYFi_board'>
          <pose frame=''>26.3301 -3.87996 1.09002 0.001161 0 2.09395</pose>
          <scale>1 1 1</scale>
          <link name='link'>
            <pose frame=''>26.3301 -3.87996 1.09002 0.001161 0 2.09395</pose>
            <velocity>0 0 0 0 -0 0</velocity>
            <acceleration>0 0 -9.8 -0 -0 -0</acceleration>
            <wrench>0 0 -9.8 0 -0 0</wrench>
          </link>
        </model>
        <model name='ebot'>
          <pose frame=''>0.010788 0.033296 0.134993 -6e-06 1.2e-05 -0.027141</pose>
          <scale>1 1 1</scale>
          <link name='FWL'>
            <pose frame=''>0.215875 0.219963 0.179996 -1.6e-05 0.186648 -0.020347</pose>
            <velocity>-0.001614 0.000552 -0.004911 0.003592 0.012904 0.000694</velocity>
            <acceleration>-3.11634 0.177455 -9.65006 -2.13729 -1.20943 -2.62776</acceleration>
            <wrench>-2.18144 0.124218 -6.75504 0 -0 0</wrench>
          </link>
          <link name='FWR'>
            <pose frame=''>0.208121 -0.161159 0.179996 3.14159 1.07582 -0.020352</pose>
            <velocity>-0.001277 0.000869 -0.00451 0.000356 0.012964 0.001064</velocity>
            <acceleration>-2.64922 0.813129 -8.99704 0.707675 -1.0253 1.52059</acceleration>
            <wrench>-1.85445 0.56919 -6.29793 0 -0 0</wrench>
          </link>
          <link name='RWL'>
            <pose frame=''>-0.184035 0.2281 0.180001 -2.5e-05 -0.177235 -0.020342</pose>
            <velocity>-0.00157 0.00039 0.003321 -0.003906 -0.0158 0.000546</velocity>
            <acceleration>-3.04803 0.127324 6.4471 2.87766 -0.007631 -2.88848</acceleration>
            <wrench>-2.13362 0.089126 4.51297 0 -0 0</wrench>
          </link>
          <link name='RWR'>
            <pose frame=''>-0.19179 -0.153023 0.18 3.14159 0.403129 -0.020348</pose>
            <velocity>-0.001323 0.000147 0.002247 -0.001458 -0.01299 0.001136</velocity>
            <acceleration>-2.72006 -0.337067 4.59558 -0.720234 -0.401524 1.43562</acceleration>
            <wrench>-1.90404 -0.235947 3.21691 0 -0 0</wrench>
          </link>
          <link name='ebot_base'>
            <pose frame=''>0.010788 0.033296 0.134993 -6e-06 1.2e-05 -0.027141</pose>
            <velocity>-0.002741 0.000597 -0.000823 0.000909 0.012977 0.000796</velocity>
            <acceleration>-1.05792 0.036613 -1.65881 1.349 0.828477 1.07875</acceleration>
            <wrench>-34.11 1.18049 -53.4843 0 -0 0</wrench>
          </link>
          <link name='forearm_link'>
            <pose frame=''>0.015152 0.049388 1.17013 -3.14145 1.03805 3.11878</pose>
            <velocity>0.007114 -0.000679 -0.000689 0.000787 0.006987 0.00822</velocity>
            <acceleration>5.29549 1.16969 0.084949 2.63148 -1.45228 -0.131048</acceleration>
            <wrench>12.0472 2.66105 0.19326 0 -0 0</wrench>
          </link>
          <link name='gripper_finger1_finger_tip_link'>
            <pose frame=''>0.354515 0.339344 0.864088 0.532573 -0.001134 1.55011</pose>
            <velocity>0.001171 -0.000283 -0.005213 -0.014411 0.011434 0.008644</velocity>
            <acceleration>1.17107 -0.283347 -5.21279 -2.76906 -0.152639 0.123012</acceleration>
            <wrench>0.0229 -0.005541 -0.101936 0 -0 0</wrench>
          </link>
          <link name='gripper_finger1_inner_knuckle_link'>
            <pose frame=''>0.321335 0.296858 0.883071 0.532569 -0.002503 1.55244</pose>
            <velocity>0.000697 0.000671 -0.003694 -0.027939 0.011672 -0.014021</velocity>
            <acceleration>0.696729 0.671241 -3.69414 2.02521 -0.138778 -1.06223</acceleration>
            <wrench>0.020868 0.020104 -0.110643 0 -0 0</wrench>
          </link>
          <link name='gripper_finger1_knuckle_link'>
            <pose frame=''>0.33662 0.290036 0.873974 0.532559 -0.002565 1.55244</pose>
            <velocity>0.000701 0.000774 -0.003808 -0.005759 0.010138 0.009476</velocity>
            <acceleration>-1.72316 1.45086 -0.388711 2.23002 0.477213 -1.56602</acceleration>
            <wrench>-0.078921 0.066449 -0.017803 0 -0 0</wrench>
          </link>
          <link name='gripper_finger2_finger_tip_link'>
            <pose frame=''>0.268067 0.341076 0.915048 -2.60903 -0.001136 1.55011</pose>
            <velocity>0.001454 0.001111 -0.004136 -0.016995 0.009312 0.010137</velocity>
            <acceleration>1.45416 1.11135 -4.1357 2.32608 -1.10665 1.76177</acceleration>
            <wrench>0.028436 0.021732 -0.080874 0 -0 0</wrench>
          </link>
          <link name='gripper_finger2_inner_knuckle_link'>
            <pose frame=''>0.299457 0.297296 0.895968 -2.60903 0.000253 1.54776</pose>
            <velocity>0.000858 0.000551 -0.00347 -0.025029 0.009424 -0.003185</velocity>
            <acceleration>0.85824 0.55083 -3.47017 -2.43008 -0.820919 -0.826522</acceleration>
            <wrench>0.025705 0.016498 -0.103935 0 -0 0</wrench>
          </link>
          <link name='gripper_finger2_knuckle_link'>
            <pose frame=''>0.283904 0.291091 0.905049 -2.60902 0.000192 1.54775</pose>
            <velocity>0.001038 0.000476 -0.003262 -0.001965 0.011031 0.015428</velocity>
            <acceleration>1.17519 0.243921 -3.07902 1.20913 1.52907 -3.04287</acceleration>
            <wrench>0.053824 0.011172 -0.141019 0 -0 0</wrench>
          </link>
          <link name='shoulder_link'>
            <pose frame=''>0.010795 0.033299 0.745152 1.7e-05 -2e-06 -0.022939</pose>
            <velocity>0.005172 4.3e-05 -0.000825 0.001104 0.020971 -0.001419</velocity>
            <acceleration>10.3619 -0.759241 -1.63832 -0.808901 -1.09126 -0.041651</acceleration>
            <wrench>38.3391 -2.80919 -6.06179 0 -0 0</wrench>
          </link>
          <link name='upper_arm_link'>
            <pose frame=''>0.01391 0.169113 0.745143 -8.3e-05 0.009382 -0.022929</pose>
            <velocity>0.002771 0.000148 -0.000397 0.001534 0.008069 0.011807</velocity>
            <acceleration>3.598 -1.06841 -0.791219 2.29435 -0.790987 -0.938529</acceleration>
            <wrench>30.198 -8.9672 -6.6407 0 -0 0</wrench>
          </link>
          <link name='wrist_1_link'>
            <pose frame=''>0.352951 0.041626 0.970895 -3.14149 -0.532362 3.11863</pose>
            <velocity>0.004613 0.002104 -0.003219 -0.00094 0.009338 0.006916</velocity>
            <acceleration>2.48582 3.8407 0.846541 1.17598 -0.312585 -2.06025</acceleration>
            <wrench>3.03022 4.68181 1.03193 0 -0 0</wrench>
          </link>
          <link name='wrist_2_link'>
            <pose frame=''>0.355081 0.1346 0.970885 3.1402 -0.532348 3.12159</pose>
            <velocity>0.003647 0.001501 -0.003095 -0.004673 0.011193 0.008197</velocity>
            <acceleration>2.26398 0.972767 1.03015 -1.43885 0.803193 -0.562837</acceleration>
            <wrench>2.7598 1.1858 1.25575 0 -0 0</wrench>
          </link>
          <link name='wrist_3_link'>
            <pose frame=''>0.307053 0.135692 0.889329 3.14021 -0.532568 3.12158</pose>
            <velocity>0.002361 0.000655 -0.00265 -0.005145 0.011021 0.009186</velocity>
            <acceleration>-0.455768 0.874923 -0.026539 2.60704 0.172965 -3.10221</acceleration>
            <wrench>-0.375945 0.72169 -0.021891 0 -0 0</wrench>
          </link>
        </model>
        <model name='glue'>
          <pose frame=''>26.29 -3.613 1.0145 -0.000102 6.8e-05 3.14</pose>
          <scale>1 1 1</scale>
          <link name='glue_link'>
            <pose frame=''>26.29 -3.613 1.0145 -0.000102 6.8e-05 3.14</pose>
            <velocity>0 0 0 0 -0 0</velocity>
            <acceleration>2e-06 -1.4e-05 -0.00096 -0.027215 -0.003434 0</acceleration>
            <wrench>0 -1e-06 -7.7e-05 0 -0 0</wrench>
          </link>
        </model>
        <model name='glue2'>
          <pose frame=''>5.31 4.3 0.869986 -0.000107 -9e-05 1.053</pose>
          <scale>1 1 1</scale>
          <link name='glue_link'>
            <pose frame=''>5.31 4.3 0.869986 -0.000107 -9e-05 1.053</pose>
            <velocity>0 0 0 0 -0 0</velocity>
            <acceleration>0 0 -9.8 0 -0 0</acceleration>
            <wrench>0 0 -0.784 0 -0 0</wrench>
          </link>
        </model>
        <model name='ground_plane'>
          <pose frame=''>0 0 0 0 -0 0</pose>
          <scale>1 1 1</scale>
          <link name='link'>
            <pose frame=''>0 0 0 0 -0 0</pose>
            <velocity>0 0 0 0 -0 0</velocity>
            <acceleration>0 0 0 0 -0 0</acceleration>
            <wrench>0 0 0 0 -0 0</wrench>
          </link>
        </model>
        <model name='office'>
          <pose frame=''>0 0 0.08 0 -0 0</pose>
          <scale>1 1 1</scale>
          <link name='link'>
            <pose frame=''>0 0 0.08 0 -0 0</pose>
            <velocity>0 0 0 0 -0 0</velocity>
            <acceleration>0 0 0 0 -0 0</acceleration>
            <wrench>0 0 0 0 -0 0</wrench>
          </link>
        </model>
        <model name='robot_wheels'>
          <pose frame=''>26.395 -3.44988 1.0531 -0.003266 0.000428 2e-05</pose>
          <scale>1 1 1</scale>
          <link name='link'>
            <pose frame=''>26.395 -3.44988 1.0531 -0.003266 0.000428 2e-05</pose>
            <velocity>0 0 0 0 -0 0</velocity>
            <acceleration>0 0 -9.8 0 -0 0</acceleration>
            <wrench>0 0 -9.8 0 -0 0</wrench>
          </link>
        </model>
        <model name='table'>
          <pose frame=''>26.608 -3.569 0 0 -0 0.934</pose>
          <scale>1 1 1</scale>
          <link name='link'>
            <pose frame=''>26.608 -3.569 0 0 -0 0.934</pose>
            <velocity>0 0 0 0 -0 0</velocity>
            <acceleration>0 0 0 0 -0 0</acceleration>
            <wrench>0 0 0 0 -0 0</wrench>
          </link>
        </model>
        <model name='water_glass'>
          <pose frame=''>10.72 -0.86 0.870491 2e-06 -2e-06 -0</pose>
          <scale>1 1 1</scale>
          <link name='link'>
            <pose frame=''>10.72 -0.86 0.870491 2e-06 -2e-06 -0</pose>
            <velocity>0 0 0 0 -0 0</velocity>
            <acceleration>0 0 -9.8 0 -0 0</acceleration>
            <wrench>0 0 -7.84 0 -0 0</wrench>
          </link>
        </model>
        <light name='sun'>
          <pose frame=''>0 0 10 0 -0 0</pose>
        </light>
      </state>
      <gui fullscreen='0'>
        <camera name='user_camera'>
          <pose frame=''>6.08677 -5.94476 2.32 0 0.275643 2.35619</pose>
          <view_controller>orbit</view_controller>
          <projection_type>perspective</projection_type>
        </camera>
      </gui>
    </world>
  </sdf>
